Workbook

Sheet 実施記録シート
B1: 【生成AI】実施記録分析シート
AR2: 分析
B3: output_row_id | C3: No. | D3: interaction_id | E3: message_id | F3: conversation_id | G3: reset_session_id | H3: reset_session_no | I3: interaction_no_in_session | J3: is_first_interaction_row | K3: 質問投入者 | L3: チーム名 | M3: 質問内容 | N3: user_content_raw | O3: is_natural_language_query | P3: is_reset_request | Q3: is_category_selection | R3: is_system_command | S3: started_at_utc | T3: completed_at_utc | U3: started_at_jst | V3: completed_at_jst | W3: latency_sec | X3: selected_function | Y3: predicted_category | Z3: user_selected_category | AA3: 第一カテゴリ | AB3: final_category | AC3: category_source | AD3: is_unclassified | AE3: 回答内容 | AF3: has_answer | AG3: is_no_answer | AH3: assistant_event_count | AI3: has_error | AJ3: error_count | AK3: error_message | AL3: retrieval_count | AM3: retrieval_stored_count | AN3: retrieval_truncated | AO3: 参照文書① | AP3: 参考箇所① | AQ3: score① | AR3: 参照文書② | AS3: 参考箇所② | AT3: score② | AU3: 参照文書➂ | AV3: 参考箇所➂ | AW3: score③ | AX3: 参照文書④ | AY3: 参考箇所④ | AZ3: score④ | BA3: 参照文書⑤ | BB3: 参考箇所⑤ | BC3: score⑤ | BD3: 参照文書⑥ | BE3: 参考箇所⑥ | BF3: score⑥ | BG3: 参照文書⑦ | BH3: 参考箇所⑦ | BI3: score⑦ | BJ3: 参照文書⑧ | BK3: 参考箇所⑧ | BL3: score⑧ | BM3: 参照文書➈ | BN3: 参考箇所➈ | BO3: score➈ | BP3: 参照文書➉ | BQ3: 参考箇所➉ | BR3: score➉ | BS3: feedback_id | BT3: feedback_seq | BU3: feedback_count | BV3: 回答評価 | BW3: 評価理由 | BX3: feedback_at_utc | BY3: feedback_at_jst | BZ3: is_latest_feedback | CA3: session_ends_with_reset | CB3: source_files | CC3: source_event_row_count | CD3: source_event_types | CE3: normalization_version | CF3: normalization_warnings | CG3: 質問/回答 分類 | CH3: 対象/ 対象外 | CI3: 参照箇所① | CJ3: 参照箇所② | CK3: 参照箇所➂ | CL3: 参照箇所④ | CM3: 参照箇所⑤ | CN3: 参照箇所⑥ | CO3: 参照箇所⑦ | CP3: 参照箇所⑧ | CQ3: 参照箇所➈ | CR3: 参照箇所➉ | CS3: 教師データ有無 | CT3: キーワード1 | CU3: キーワード2 | CV3: キーワード3 | CW3: Hit判定 | CX3: 回答判定 | CY3: 正答判定 | CZ3: 分析コメント | DA3: 原因 | DB3: 対応方針 | DC3: 対応進捗 | DD3: Vantiq相談 | DE3: 日付 | DF3: 所属 | DG3: messageID
B4: a:1omqjbhub5JIc_5FhNKbUGVjE57wIHZd4XRyWB2-vQ88Xs_NQ3anUe3ETxUmMWwvMWebbd9pg74lN0B4BHFnuC8XT7VOk1CrVz5XQuTIU29Pc-C2tG70xw6Ef9QslptPg-1779142431837-FB000 | C4: =ROW(A4)-3 | D4: a:1omqjbhub5JIc_5FhNKbUGVjE57wIHZd4XRyWB2-vQ88Xs_NQ3anUe3ETxUmMWwvMWebbd9pg74lN0B4BHFnuC8XT7VOk1CrVz5XQuTIU29Pc-C2tG70xw6Ef9QslptPg-1779142431837 | E4: 1779142431837 | F4: a:1omqjbhub5JIc_5FhNKbUGVjE57wIHZd4XRyWB2-vQ88Xs_NQ3anUe3ETxUmMWwvMWebbd9pg74lN0B4BHFnuC8XT7VOk1CrVz5XQuTIU29Pc-C2tG70xw6Ef9QslptPg | G4: a:1omqjbhub5JIc_5FhNKbUGVjE57wIHZd4XRyWB2-vQ88Xs_NQ3anUe3ETxUmMWwvMWebbd9pg74lN0B4BHFnuC8XT7VOk1CrVz5XQuTIU29Pc-C2tG70xw6Ef9QslptPg-S001 | H4: 1 | I4: 1 | J4: 1 | K4: Hiromichi Nagano (長野 裕充) | L4: DM | M4: 上長設定を変更したい。 | N4: 上長設定を変更したい。 | O4: 1 | P4: 0 | Q4: 0 | R4: 0 | S4: 46160.926 | T4: 46160.926 | U4: 46161.301 | V4: 46161.301 | W4: 5.374 | X4: searchEmployeeRules | Y4: システム操作 | AA4: システム操作 | AB4: システム操作 | AC4: predicted | AD4: 0 | AE4: 上長設定の変更方法については、以下のURLで詳細な手順が案内されています。 https://www.hdservice1.nttls.co.jp/hc/ja/articles/19023196852503 上記のページをご確認いただくことで、具体的な操作方法や注意点を確認できます。 ※AIの回答は必ずしも正確ではありません。参照情報も確認いただき、最終判断は所属部署の公式情報をご確認ください。 | AF4: 1 | AG4: 0 | AH4: 3 | AI4: 0 | AJ4: 0 | AL4: 4 | AM4: 4 | AN4: 0 | AO4: QA592_system_talemane_talemane-employee.md | AP4: 質問 派遣社員から上長設定する方法を教えてください。 回答 派遣社員から上長設定する方法がわからない場合は以下URLをご確認ください。 https://www.hdservice1.nttls.co.jp/hc/ja/articles/19023196852503 | AQ4: 0.93496073 | AR4: QA620_system_talemane_talemane-employee.md | AS4: 質問 上長設定を変更したのに申請の承認が新上長に表示されない場合、どうしたらいいでしょうか。 回答 上長設定を変更したのに申請の承認が新上長に表示されない場合は以下URLをご確認ください。 https://www.hdservice1.nttls.co.jp/hc/ja/articles/360057335353 | AT4: 0.94158808 | AU4: QA617_system_talemane_talemane-employee.md | AV4: 質問 上長が社員のポジションを割り当てることができない場合、どうしたらいいでしょうか。 回答 上長が社員のポジションを割り当てることができない場合は以下URLをご確認ください。 https://www.hdservice1.nttls.co.jp/hc/ja/articles/25013787582487 | AW4: 0.93496073 | AX4: QA614_system_talemane_talemane-employee.md | AY4: 質問 プロファイル画面から上長設定を行って新上長に変更したが、「一次評価者」が異なったまま(古い情報のまま)となっている場合、どうしたらいいでしょうか。 回答 「一次評価者」が異なったまま(古い情報のまま)となっている場合は以下URLをご確認ください。 https://www.hdservice1.nttls.co.jp/hc/ja/articles/17842855242519 | AZ4: 0.92931769 | BT4: 0 | BU4: 0 | BZ4: 0 | CA4: 0 | CB4: 20260519T071352-20260519T182604.csv | CC4: 5 | CD4: user > assistant > assistant > tool > assistant | CE4: 1.0.0 | CH4: =IF(OR(CG4="①", CG4="⑤"), "〇", "×") | CI4: =IF(OR(AND($CT4<>"",ISNUMBER(SEARCH($CT4, AP4))),AND($CU4<>"",ISNUMBER(SEARCH($CU4, AP4))),AND($CV4<>"",ISNUMBER(SEARCH($CV4, AP4)))),"〇","-") | CJ4: =IF(OR(AND($CT4<>"",ISNUMBER(SEARCH($CT4, AS4))),AND($CU4<>"",ISNUMBER(SEARCH($CU4, AS4))),AND($CV4<>"",ISNUMBER(SEARCH($CV4, AS4)))),"〇","-") | CK4: =IF(OR(AND($CT4<>"",ISNUMBER(SEARCH($CT4, AV4))),AND($CU4<>"",ISNUMBER(SEARCH($CU4, AV4))),AND($CV4<>"",ISNUMBER(SEARCH($CV4, AV4)))),"〇","-") | CL4: =IF(OR(AND($CT4<>"",ISNUMBER(SEARCH($CT4, AY4))),AND($CU4<>"",ISNUMBER(SEARCH($CU4, AY4))),AND($CV4<>"",ISNUMBER(SEARCH($CV4, AY4)))),"〇","-") | CM4: =IF(OR(AND($CT4<>"",ISNUMBER(SEARCH($CT4, BB4))),AND($CU4<>"",ISNUMBER(SEARCH($CU4, BB4))),AND($CV4<>"",ISNUMBER(SEARCH($CV4, BB4)))),"〇","-") | CN4: =IF(OR(AND($CT4<>"",ISNUMBER(SEARCH($CT4, BE4))),AND($CU4<>"",ISNUMBER(SEARCH($CU4, BE4))),AND($CV4<>"",ISNUMBER(SEARCH($CV4, BE4)))),"〇","-") | CO4: =IF(OR(AND($CT4<>"",ISNUMBER(SEARCH($CT4, BH4))),AND($CU4<>"",ISNUMBER(SEARCH($CU4, BH4))),AND($CV4<>"",ISNUMBER(SEARCH($CV4, BH4)))),"〇","-") | CP4: =IF(OR(AND($CT4<>"",ISNUMBER(SEARCH($CT4, BK4))),AND($CU4<>"",ISNUMBER(SEARCH($CU4, BK4))),AND($CV4<>"",ISNUMBER(SEARCH($CV4, BK4)))),"〇","-") | CQ4: =IF(OR(AND($CT4<>"",ISNUMBER(SEARCH($CT4, BN4))),AND($CU4<>"",ISNUMBER(SEARCH($CU4, BN4))),AND($CV4<>"",ISNUMBER(SEARCH($CV4, BN4)))),"〇","-") | CR4: =IF(OR(AND($CT4<>"",ISNUMBER(SEARCH($CT4, BQ4))),AND($CU4<>"",ISNUMBER(SEARCH($CU4, BQ4))),AND($CV4<>"",ISNUMBER(SEARCH($CV4, BQ4)))),"〇","-") | CW4: =IF(OR(CI4="〇",CJ4="〇",CK4="〇",CL4="〇",CM4="〇",CN4="〇",CO4="〇",CP4="〇",CQ4="〇",CR4="〇"),"〇","") | DE4: =TEXT(U4,"yyyy/mm/dd") | DF4: =VLOOKUP(K4,社員マスタ!C:D,2,0) | DG4: 1779142431837
B5: a:1iSKy7qXCPUl6lHy-2B3xgvRc_tKz1v0JykSQbNaMY5vJSp_4_w19tMqhUwM_oTGTKXV3N-8UzSVsmI-kFbz0LUhY29S-4UuWaWst7uPr3IGvm-BhrKY6KzPsnWAHxMJR-1779150199248-FB000 | C5: =ROW(A5)-3 | D5: a:1iSKy7qXCPUl6lHy-2B3xgvRc_tKz1v0JykSQbNaMY5vJSp_4_w19tMqhUwM_oTGTKXV3N-8UzSVsmI-kFbz0LUhY29S-4UuWaWst7uPr3IGvm-BhrKY6KzPsnWAHxMJR-1779150199248 | E5: 1779150199248 | F5: a:1iSKy7qXCPUl6lHy-2B3xgvRc_tKz1v0JykSQbNaMY5vJSp_4_w19tMqhUwM_oTGTKXV3N-8UzSVsmI-kFbz0LUhY29S-4UuWaWst7uPr3IGvm-BhrKY6KzPsnWAHxMJR | G5: a:1iSKy7qXCPUl6lHy-2B3xgvRc_tKz1v0JykSQbNaMY5vJSp_4_w19tMqhUwM_oTGTKXV3N-8UzSVsmI-kFbz0LUhY29S-4UuWaWst7uPr3IGvm-BhrKY6KzPsnWAHxMJR-S001 | H5: 1 | I5: 1 | J5: 1 | K5: Kazuyo Sorimachi (返町 和代) | L5: DM | M5: 添付の画面キャプチャのように、休憩時間と時間休を連続させてもよいのでしょうか？ | N5: 添付の画面キャプチャのように、休憩時間と時間休を連続させてもよいのでしょうか？ | O5: 1 | P5: 0 | Q5: 0 | R5: 0 | S5: 46161.016 | T5: 46161.016 | U5: 46161.391 | V5: 46161.391 | W5: 5.706 | X5: searchEmployeeRules | Y5: 制度・運用 | AA5: 制度・運用 | AB5: 制度・運用 | AC5: predicted | AD5: 0 | AE5: 休憩時間は勤務の途中において、継続または分割して与えられると定められています。 この規定から、休憩時間と時間休（年次休暇などの時間単位休暇）を連続して取得すること自体は、特に禁止されていません。 ただし、勤務形態や制度によって細かい運用が異なる場合もあるため、実際の申請時には所属部署のルールや運用状況を確認することが望ましいです。 ※AIの回答は必ずしも正確ではありません。参照情報も確認いただき、最終判断は所属部署の公式情報をご確認ください。 | AF5: 1 | AG5: 0 | AH5: 3 | AI5: 0 | AJ5: 0 | AL5: 4 | AM5: 4 | AN5: 0 | AO5: 02 臨時雇就業規則_202512.docx | AP5: ２ 前項の始業及び終業の時刻は、業務の都合又は本人の希望により変更することがある。 休憩時間 第 11 条 休憩時間は、少なくとも拘束２時間について15分の割合で計算した時間を与えられる。 ただし、勤務時間が拘束４時間以下であるときは与えられないことがある。 ２ 休憩時間は勤務の途中において、継続し、又は分割して与えられる。 時間外及び休日の勤務 第 12 条 １日について勤務時間８時間、１週間について勤務時間40時間を超えない限りにおいて第９条及び第14条の規定にかかわらず、１日の所定勤務時間を超えて、又は４週４日以外の休日に勤務を命ぜられることがある。 ２ 次の各号の一に該当する場合においては、前項の規定にかかわらず、時間外又は休日に勤務を命ぜられることがある。 (1) 労働基準法第36条の規定により協定を締結したとき (2) 労働基準法第33条の規定により労働基準監督署に所定の手続きをしたとき ３ 労働基準法第41条第３号の許可を受けた者は、前各項の規定にかかわらず、時間外又は休日に勤務を命ぜられることがある。 第２節 リモートワーク リモートワーク 第 13 条 臨時雇が所属長にリモートワークを申し出たとき、または会社指示により、勤務事業所以外を勤務場所とすることがある。 ２ 会社が貸与する情報通信機器等を除き、リモートワークに関わる費用については、臨時雇が負担する。 第３節 休日及び休暇 休 日 第 14 条 休日は、原則として次のとおりとし、４週４日を下回らないよう個別の雇用契約において定める。 (1) 毎週日曜日及び土曜日 (2) 個別の雇用契約において定めた日 ２ 前項の休日は、業務上やむを得ない理由があるときは、他の日に変更されることがある。 休暇の種類 第 15 条 休暇には、次の種類がある。 （１）有給休暇 ア 年次休暇 イ 特別休暇 ウ 病気休暇 エ 特別連続休暇 （２）無給休暇 ア 看護等休暇 イ 介護のための短期の休暇 （３）その他 ア 公傷休暇 イ 通勤災害休暇 ２ 前項の休暇のほか、社長が必要と認めた場合に休暇が与えられることがある。 年次休暇 | AQ5: 0.90772143 | AR5: 36 社員の勤務時間、休日及び休暇について_202504.docx | AS5: （８）宿直宿明服務の全勤務時間にかかる休暇は、１日単位の休暇２回とする。 （９）勤務軽減の措置により休養時間を与えている社員が休暇を取得する場合においては、その社員の所定の拘束時間は、休養時間を与えない場合の時間とし、休暇が休養時間と連続する場合は、その休養時間は与えなかったものとして取り扱う。 ６ 勤務時間の変更があった場合の取扱い 全日制勤務の社員が「育児のための短時間勤務制度について」(2007年４月１日人育服第６号)に定める育児のための短時間勤務又は「介護休職及び介護のための短時間勤務制度について」（1992年７月１日総第121号）第５項に定める介護のための短時間勤務（以下、「育児又は介護のための短時間勤務」という。）を取得する場合、育児又は介護のための短時間勤務を取得している社員が１日の勤務時間を変更する場合又は全日制勤務に復帰する場合（以下、「勤務時間の変更」という。）、変更又は復帰後の１時間を単位とする年次休暇の保有時間数については、以下の通りとする。 変更前の １日の勤務時間 変更後の １日の勤務時間 変更又は復帰後の保有時間数 ７時間30分 ６時間 変更又は復帰前に保有する時間数に ８分の６を乗じて得た時間数 ５時間 変更又は復帰前に保有する時間数に ８分の５を乗じて得た時間数 ４時間 変更又は復帰前に保有する時間数に ８分の４を乗じて得た時間数 ６時間 ７時間30分 変更又は復帰前に保有する時間数に ６分の８を乗じて得た時間数 ５時間 変更又は復帰前に保有する時間数に ６分の５を乗じて得た時間数 ４時間 変更又は復帰前に保有する時間数に ６分の４を乗じて得た時間数 ５時間 ７時間30分 変更又は復帰前に保有する時間数に ５分の８を乗じて得た時間数 ６時間 変更又は復帰前に保有する時間数に ５分の６を乗じて得た時間数 ４時間 変更又は復帰前に保有する時間数に ５分の４を乗じて得た時間数 ４時間 ７時間30分 変更又は復帰前に保有する時間数に ４分の８を乗じて得た時間数 ６時間 変更又は復帰前に保有する時間数に ４分の６を乗じて得た時間数 ５時間 変更又は復帰前に保有する時間数に ４分の５を乗じて得た時間数 なお、保有時間数に１時間未満の端数がある場合は、端数を切り上げた時間数に読み替える。 ７ 給 与 年次休暇は、有給とする。 | AT5: 0.9074277 | AU5: 健康管理規程.pdf | AV5: ア 日勤服務以外の服務につかせない。ただし、やむを得ぬ理由で夜勤服務につかせる場合は、組織の 長と産業医が協議して決める。 イ 健康状態に応じて、勤務時間中に休養時間を与えるか、又は作業環境、労働負荷を考慮して、勤務 内容の軽減をはかる。 (ｱ) 休養時間中は、原則として事業所内の休憩室等で休養させる。ただし、通勤所要時間、交通機 関等の諸事情を考慮して、勤務の始め又は終りに休養時間を与えることができる。 (ｲ) 休養時間は、１日の所定勤務時間から休養時間を除いた時間が、拘束４時間を下回らない範囲 で与えるものとする。 (ｳ) 勤務内容の軽減をはかる場合には、必要に応じて勤務場所の変更、業務の転換等を行うものと する。 ウ 過激な運動を伴う業務、時間外労働、宿泊出張はさせない。 (3) 要注意（Ｃ）の服務については、次の各項によることとする。 ア 日勤服務以外の服務につかせない。ただし、やむを得ぬ理由で前記の服務以外の服務につかせる場 合は、組織の長と産業医が協議して決める。 イ 時間外労働はさせない。ただし、やむを得ぬ理由で時間外労働をさせる場合は、組織の長と産業医 が協議して決める。この場合においても、１日２時間、１週２回を限度とする。 | AW5: 0.90772143 | AX5: 01 社員就業規則等_202512.docx | AY5: ２ 宿直については、睡眠時間を含み８時間以内の休憩時間が与えられる。 ３ 日直又は宿直の当直時間については、所属長が定めるところによる。 出張、赴任等の場合の勤務時間 第 29 条 社員が出張し、若しくは赴任し、又は所属長のもとを離れて勤務する場合における勤務時間については、特に命ぜられた場合を除くほか、所定の勤務時間を勤務したものとみなす。 第２節 フレックスタイム制 対象者 第 30 条 社員は、第20条から第27条までの規定にかかわらず、次条以下に規定するフレックスタイム制が適用されることがある。 基準労働時間 第 31 条 前条に定める社員は、各清算期間（各月１日から月末まで）において、基準労働時間（週休日を日曜日及び土曜日に設定する社員の当該清算期間における所定労働日の勤務時間（１日７時間30分。ただし、第64条第３項及び第67条第２項に規定する短時間勤務を行う者については、１日４時間、５時間又は６時間のいずれかの時間）を合計して得た時間をいう。）を勤務しなければならない。 コアタイム及びフレキシブルタイム 第 32 条 コアタイム及びフレキシブルタイムは、次のとおりとする。 （１） コアタイム（全員が勤務しなければならない時間帯） ① 標準的なコアタイムは、午前10時から午後３時まで（正午から午後１時までは休憩時間）の４時間とする。 なお、具体的な設定時刻は、労働基準法第32条の３に規定する協定により定める。 ② 第64条第３項及び第67条第２項に規定する短時間勤務を行う者の標準的なコアタイムは、午前10時から午後２時（正午から午後１時までは休憩時間）の３時間とする。なお、具体的な設定時刻は、労働基準法第32条の３に規定する協定により定める。 ③ コアタイムを設定しない場合は、１日の最低勤務時間を３時間とする。 なお、具体的には労働基準法第32条の３に規定する協定により定める。 また、コアタイムを設定しない場合における休憩時間は、次のとおりとし、勤務の途中において適用社員の裁量により設定する。 ア １日５時間以上７時間未満の勤務 45分 イ １日７時間以上の勤務 60分 （２）フレキシブルタイム（社員が自主的に始業・終業時刻を選択できる時間帯） | AZ5: 0.90791325 | BT5: 0 | BU5: 0 | BZ5: 0 | CA5: 1 | CB5: 20260519T071352-20260519T182604.csv | CC5: 5 | CD5: user > assistant > assistant > tool > assistant | CE5: 1.0.0 | CH5: =IF(OR(CG5="①", CG5="⑤"), "〇", "×") | CI5: =IF(OR(AND($CT5<>"",ISNUMBER(SEARCH($CT5, AP5))),AND($CU5<>"",ISNUMBER(SEARCH($CU5, AP5))),AND($CV5<>"",ISNUMBER(SEARCH($CV5, AP5)))),"〇","-") | CJ5: =IF(OR(AND($CT5<>"",ISNUMBER(SEARCH($CT5, AS5))),AND($CU5<>"",ISNUMBER(SEARCH($CU5, AS5))),AND($CV5<>"",ISNUMBER(SEARCH($CV5, AS5)))),"〇","-") | CK5: =IF(OR(AND($CT5<>"",ISNUMBER(SEARCH($CT5, AV5))),AND($CU5<>"",ISNUMBER(SEARCH($CU5, AV5))),AND($CV5<>"",ISNUMBER(SEARCH($CV5, AV5)))),"〇","-") | CL5: =IF(OR(AND($CT5<>"",ISNUMBER(SEARCH($CT5, AY5))),AND($CU5<>"",ISNUMBER(SEARCH($CU5, AY5))),AND($CV5<>"",ISNUMBER(SEARCH($CV5, AY5)))),"〇","-") | CM5: =IF(OR(AND($CT5<>"",ISNUMBER(SEARCH($CT5, BB5))),AND($CU5<>"",ISNUMBER(SEARCH($CU5, BB5))),AND($CV5<>"",ISNUMBER(SEARCH($CV5, BB5)))),"〇","-") | CN5: =IF(OR(AND($CT5<>"",ISNUMBER(SEARCH($CT5, BE5))),AND($CU5<>"",ISNUMBER(SEARCH($CU5, BE5))),AND($CV5<>"",ISNUMBER(SEARCH($CV5, BE5)))),"〇","-") | CO5: =IF(OR(AND($CT5<>"",ISNUMBER(SEARCH($CT5, BH5))),AND($CU5<>"",ISNUMBER(SEARCH($CU5, BH5))),AND($CV5<>"",ISNUMBER(SEARCH($CV5, BH5)))),"〇","-") | CP5: =IF(OR(AND($CT5<>"",ISNUMBER(SEARCH($CT5, BK5))),AND($CU5<>"",ISNUMBER(SEARCH($CU5, BK5))),AND($CV5<>"",ISNUMBER(SEARCH($CV5, BK5)))),"〇","-") | CQ5: =IF(OR(AND($CT5<>"",ISNUMBER(SEARCH($CT5, BN5))),AND($CU5<>"",ISNUMBER(SEARCH($CU5, BN5))),AND($CV5<>"",ISNUMBER(SEARCH($CV5, BN5)))),"〇","-") | CR5: =IF(OR(AND($CT5<>"",ISNUMBER(SEARCH($CT5, BQ5))),AND($CU5<>"",ISNUMBER(SEARCH($CU5, BQ5))),AND($CV5<>"",ISNUMBER(SEARCH($CV5, BQ5)))),"〇","-") | CW5: =IF(OR(CI5="〇",CJ5="〇",CK5="〇",CL5="〇",CM5="〇",CN5="〇",CO5="〇",CP5="〇",CQ5="〇",CR5="〇"),"〇","") | DE5: =TEXT(U5,"yyyy/mm/dd") | DF5: =VLOOKUP(K5,社員マスタ!C:D,2,0) | DG5: 1779150199248
B6: a:1iSKy7qXCPUl6lHy-2B3xgvRc_tKz1v0JykSQbNaMY5vJSp_4_w19tMqhUwM_oTGTKXV3N-8UzSVsmI-kFbz0LUhY29S-4UuWaWst7uPr3IGvm-BhrKY6KzPsnWAHxMJR-1779150903232-FB000 | C6: =ROW(A6)-3 | D6: a:1iSKy7qXCPUl6lHy-2B3xgvRc_tKz1v0JykSQbNaMY5vJSp_4_w19tMqhUwM_oTGTKXV3N-8UzSVsmI-kFbz0LUhY29S-4UuWaWst7uPr3IGvm-BhrKY6KzPsnWAHxMJR-1779150903232 | E6: 1779150903232 | F6: a:1iSKy7qXCPUl6lHy-2B3xgvRc_tKz1v0JykSQbNaMY5vJSp_4_w19tMqhUwM_oTGTKXV3N-8UzSVsmI-kFbz0LUhY29S-4UuWaWst7uPr3IGvm-BhrKY6KzPsnWAHxMJR | G6: a:1iSKy7qXCPUl6lHy-2B3xgvRc_tKz1v0JykSQbNaMY5vJSp_4_w19tMqhUwM_oTGTKXV3N-8UzSVsmI-kFbz0LUhY29S-4UuWaWst7uPr3IGvm-BhrKY6KzPsnWAHxMJR-S001 | H6: 1 | I6: 2 | J6: 1 | K6: Kazuyo Sorimachi (返町 和代) | L6: DM | M6: 休暇種別のうちの「不稼働」とは何ですか？ どういうときに使うのですか？ | N6: 休暇種別のうちの「不稼働」とは何ですか？ どういうときに使うのですか？ | O6: 1 | P6: 0 | Q6: 0 | R6: 0 | S6: 46161.024 | T6: 46161.024 | U6: 46161.399 | V6: 46161.399 | W6: 6.798 | X6: searchEmployeeRules | AB6: 未分類 | AC6: none | AD6: 1 | AE6: 検索結果から「不稼働」に関する直接的な定義や具体的な使用場面の記載は見当たりませんでした。 「不稼働」は一般的に、業務上の必要に基づく事務の一部または全部の停止など、会社側の事情で勤務ができない場合に使われる休暇種別です。 例えば、業務上の必要で事務が停止された場合や、非常事態の発生により出勤・勤務が不可能な場合などが該当します。 このようなケースでは、所属長が必要と認める時間や日数で「不稼働」として扱われることがあります。 ※AIの回答は必ずしも正確ではありません。参照情報も確認いただき、最終判断は所属部署の公式情報をご確認ください。 | AF6: 1 | AG6: 0 | AH6: 2 | AI6: 0 | AJ6: 0 | AL6: 4 | AM6: 4 | AN6: 0 | AO6: 40 特認休暇について_202511.docx | AP6: （注）(1) 休暇を付与する場合であって、特に必要とする場合は、臨時雇を雇用しても差し支えない。 「業務に支障がない場合」には、「業務に支障があるが、臨時雇を雇用すれば業務に支障がなくなる場合」を含む。 ２ 前項による休暇の付与は、次により行うものとする。 (1) 「休暇願」（「人事服務関係の願、届について」（1992年７月１日総第22号）に定める様式）に基づき、組織単位の長（組織単位の長が指定した者（直属上長より上位にある者に限る。）を含む。）が承認する。 (2) １年につき６週間以内であれば、夏季及び冬季の２回付与しても差し支えない。 (3) １学部の受講につき24週間以内であれば、５年以上にわたって付与しても差し支えない。 ３ 第１項に定める休暇は、社員就業規則第37条第２項による休暇とし、有給とする。 ４ 第１項に定める休暇期間中の給与については、基本給、成果手当及び採用調整加算の合算した額の10分の3を減額して得た額並びに子育て・介護手当、単身赴任手当及び住宅補助費の全額を支給するものとする。 この場合、月の初日以外の日において新たにこの休暇を付与した場合又は月の末日以外の日においてこの休暇期間が終了した場合における減額すべき額については、「社員給与規則の解釈運用について」（1992年７月１日総第45号）第11条第１項の算出式に基づき、日割によって計算するものとする。 付 則 １ 本通達は、2023年４月１日から実施する。 ２ 「第５章 大学通信教育のスクーリングに参加する者の服務の取扱について」第４項の休暇期間中の給与において、「社員給与規則」（1992年７月１日社長達第22号）の改正（2023年３月31日）付則第３項ないし第12項の措置額を含めて扱う。 ３ 本通達の実施に伴い、「特認休暇について」（1992年7月1日総第16号）、「ＮＴＴドコモグループ記念日における服務等の取扱いについて」（1992年９月24日総第294号）、「被災者支援活動に従事する社員の服務について」（1995年５月15日総勤第２号）、「骨髄バンクへの登録等を行う社員の服務について」（1993年12月24日総勤第78号）及び「大学通信教育のスクーリングに参加する者の服務の取扱について」（1992年７月１日総第23号）を廃止する。 付 則 | AQ6: 0.9295409 | AR6: 02 臨時雇就業規則_202512.docx | AS6: る。 ２ 前項における出勤率の算定にあたっては、第17条第１項第15号に定める出産のための特別休暇、第20条に定める公傷休暇、第29条に定める育児休職及び第30条に定める介護休職を付与した日は出勤したものとみなす。 ３ 年次休暇を与えた日の賃金は、当該勤務日の所定勤務時間を勤務した場合に支払われる通常の賃金とする。 ４ 年次休暇の時季の指定等の取扱いは次のとおりとする。 （1）年次休暇の時季を指定する場合は事前に行わなければならない。 ただし、指定された時季における年次休暇が事業の正常な運営を妨げる場合は、会社は他の時季に変更することができるものとする。 （2）同条第１項の年次休暇が10日以上発効された臨時雇に対して、発効日から１年以内の年次休暇の取得日数が日又は半日単位で５日に満たない場合は、その不足分について、臨時雇の希望を勘案したうえで会社があらかじめ時季を指定し、日又は半日を単位に取得させることとする。 ５ 年次休暇は、原則として日を単位とするが、１時間を単位とすることもできる。 ただし、１時間を単位とした休暇は、休暇発効日より１年以内において５日を上限とする。 なお、休暇の付与日数が５日に満たない場合、発効された日数を上限とする。 ６ １時間を単位とする場合における取り扱いは、次のとおりとする。 (1) １時間を単位とした休暇は１日の所定勤務時間内において、取得時間帯、取得時間数に制限無く取得できる。 (2) １時間単位の休暇は、１日の所定勤務時間数をもって１日分とする。 特別休暇 第 17 条 臨時雇が次の各号の一に該当する理由により勤務日に勤務しないときは、当該各号に定 めるところにより、その者に特別休暇が与えられる。 | AT6: 0.92628923 | AU6: 50 社員の選挙運動等の取扱について_200807.docx | AV6: イ 選挙運動期間中における年次休暇の取扱いについては、通常における場合と同様厳正に取り扱うものとし、組合休暇については、それを選挙運動等のために使用することのないよう厳正に取り扱うこと。 ウ 選挙運動のための会社の業務用電話の利用、会社車両の使用の承認、タクシー利用券の交付、その他これに類する便宜供与は行ってはならない。 エ 特定の候補者を支援することの疑惑を世間に抱かせるような物品の購入等の行為は厳に慎むこと。 当然のことながら、勤務時間内に会社組織を利用して資金カンパ等を行うことも同様行ってはならない。 ３ 選挙運動に係る会社施設の利用等について 会社施設（宿舎を含む。）の利用について申出があった場合、その目的、内容が自ら選挙運動又は政治的な活動を行うためのものであると認められるときは、これの使用を一切認めないこと。 選挙運動のために使用するポスター等の指示についても、その内容が選挙運動又は政治的な活動に関係があると認められるものはこれを認めないこと。 ４ その他 社員が国会又は地方公共団体の議会の議員その他公選による公職の選挙に立候補するときは、所属長に公職立候補届を提出しなければならない。 社員が前１の公職に就任するときは、すみやかに所属長に当選証明書を提出しなければならない。 | AW6: 0.9295409 | AX6: 健康管理規程.pdf | AY6: ア 日勤服務以外の服務につかせない。ただし、やむを得ぬ理由で夜勤服務につかせる場合は、組織の 長と産業医が協議して決める。 イ 健康状態に応じて、勤務時間中に休養時間を与えるか、又は作業環境、労働負荷を考慮して、勤務 内容の軽減をはかる。 (ｱ) 休養時間中は、原則として事業所内の休憩室等で休養させる。ただし、通勤所要時間、交通機 関等の諸事情を考慮して、勤務の始め又は終りに休養時間を与えることができる。 (ｲ) 休養時間は、１日の所定勤務時間から休養時間を除いた時間が、拘束４時間を下回らない範囲 で与えるものとする。 (ｳ) 勤務内容の軽減をはかる場合には、必要に応じて勤務場所の変更、業務の転換等を行うものと する。 ウ 過激な運動を伴う業務、時間外労働、宿泊出張はさせない。 (3) 要注意（Ｃ）の服務については、次の各項によることとする。 ア 日勤服務以外の服務につかせない。ただし、やむを得ぬ理由で前記の服務以外の服務につかせる場 合は、組織の長と産業医が協議して決める。 イ 時間外労働はさせない。ただし、やむを得ぬ理由で時間外労働をさせる場合は、組織の長と産業医 が協議して決める。この場合においても、１日２時間、１週２回を限度とする。 | AZ6: 0.92568737 | BT6: 0 | BU6: 0 | BZ6: 0 | CA6: 1 | CB6: 20260519T071352-20260519T182604.csv | CC6: 4 | CD6: user > assistant > tool > assistant | CE6: 1.0.0 | CH6: =IF(OR(CG6="①", CG6="⑤"), "〇", "×") | CI6: =IF(OR(AND($CT6<>"",ISNUMBER(SEARCH($CT6, AP6))),AND($CU6<>"",ISNUMBER(SEARCH($CU6, AP6))),AND($CV6<>"",ISNUMBER(SEARCH($CV6, AP6)))),"〇","-") | CJ6: =IF(OR(AND($CT6<>"",ISNUMBER(SEARCH($CT6, AS6))),AND($CU6<>"",ISNUMBER(SEARCH($CU6, AS6))),AND($CV6<>"",ISNUMBER(SEARCH($CV6, AS6)))),"〇","-") | CK6: =IF(OR(AND($CT6<>"",ISNUMBER(SEARCH($CT6, AV6))),AND($CU6<>"",ISNUMBER(SEARCH($CU6, AV6))),AND($CV6<>"",ISNUMBER(SEARCH($CV6, AV6)))),"〇","-") | CL6: =IF(OR(AND($CT6<>"",ISNUMBER(SEARCH($CT6, AY6))),AND($CU6<>"",ISNUMBER(SEARCH($CU6, AY6))),AND($CV6<>"",ISNUMBER(SEARCH($CV6, AY6)))),"〇","-") | CM6: =IF(OR(AND($CT6<>"",ISNUMBER(SEARCH($CT6, BB6))),AND($CU6<>"",ISNUMBER(SEARCH($CU6, BB6))),AND($CV6<>"",ISNUMBER(SEARCH($CV6, BB6)))),"〇","-") | CN6: =IF(OR(AND($CT6<>"",ISNUMBER(SEARCH($CT6, BE6))),AND($CU6<>"",ISNUMBER(SEARCH($CU6, BE6))),AND($CV6<>"",ISNUMBER(SEARCH($CV6, BE6)))),"〇","-") | CO6: =IF(OR(AND($CT6<>"",ISNUMBER(SEARCH($CT6, BH6))),AND($CU6<>"",ISNUMBER(SEARCH($CU6, BH6))),AND($CV6<>"",ISNUMBER(SEARCH($CV6, BH6)))),"〇","-") | CP6: =IF(OR(AND($CT6<>"",ISNUMBER(SEARCH($CT6, BK6))),AND($CU6<>"",ISNUMBER(SEARCH($CU6, BK6))),AND($CV6<>"",ISNUMBER(SEARCH($CV6, BK6)))),"〇","-") | CQ6: =IF(OR(AND($CT6<>"",ISNUMBER(SEARCH($CT6, BN6))),AND($CU6<>"",ISNUMBER(SEARCH($CU6, BN6))),AND($CV6<>"",ISNUMBER(SEARCH($CV6, BN6)))),"〇","-") | CR6: =IF(OR(AND($CT6<>"",ISNUMBER(SEARCH($CT6, BQ6))),AND($CU6<>"",ISNUMBER(SEARCH($CU6, BQ6))),AND($CV6<>"",ISNUMBER(SEARCH($CV6, BQ6)))),"〇","-") | CW6: =IF(OR(CI6="〇",CJ6="〇",CK6="〇",CL6="〇",CM6="〇",CN6="〇",CO6="〇",CP6="〇",CQ6="〇",CR6="〇"),"〇","") | DE6: =TEXT(U6,"yyyy/mm/dd") | DF6: =VLOOKUP(K6,社員マスタ!C:D,2,0) | DG6: 1779150903232
B7: a:1iSKy7qXCPUl6lHy-2B3xgvRc_tKz1v0JykSQbNaMY5vJSp_4_w19tMqhUwM_oTGTKXV3N-8UzSVsmI-kFbz0LUhY29S-4UuWaWst7uPr3IGvm-BhrKY6KzPsnWAHxMJR-1779151036941-FB000 | C7: =ROW(A7)-3 | D7: a:1iSKy7qXCPUl6lHy-2B3xgvRc_tKz1v0JykSQbNaMY5vJSp_4_w19tMqhUwM_oTGTKXV3N-8UzSVsmI-kFbz0LUhY29S-4UuWaWst7uPr3IGvm-BhrKY6KzPsnWAHxMJR-1779151036941 | E7: 1779151036941 | F7: a:1iSKy7qXCPUl6lHy-2B3xgvRc_tKz1v0JykSQbNaMY5vJSp_4_w19tMqhUwM_oTGTKXV3N-8UzSVsmI-kFbz0LUhY29S-4UuWaWst7uPr3IGvm-BhrKY6KzPsnWAHxMJR | G7: a:1iSKy7qXCPUl6lHy-2B3xgvRc_tKz1v0JykSQbNaMY5vJSp_4_w19tMqhUwM_oTGTKXV3N-8UzSVsmI-kFbz0LUhY29S-4UuWaWst7uPr3IGvm-BhrKY6KzPsnWAHxMJR-S001 | H7: 1 | I7: 3 | J7: 1 | K7: Kazuyo Sorimachi (返町 和代) | L7: DM | M7: DREAMSの休暇種別で選択できるようになっているのですが、制度の説明はありませんか？ | N7: DREAMSの休暇種別で選択できるようになっているのですが、制度の説明はありませんか？ | O7: 1 | P7: 0 | Q7: 0 | R7: 0 | S7: 46161.026 | T7: 46161.026 | U7: 46161.401 | V7: 46161.401 | W7: 4.702 | X7: searchEmployeeRules | AB7: 未分類 | AC7: none | AD7: 1 | AE7: ご質問の内容に関する情報が見つかりませんでした。 以下操作を行っていただくことで回答を得やすくなるのでお試しください。 * 「カテゴリ」を選択：質問要件が絞りこまれることで回答が得やすくなります。 * 「リセット」を選択：会話記録をリセットすることで回答が得やすくなります。 * 「ヘルプ」を選択 ：回答が得やすくなるヒントが確認できます。 有人での確認が必要な内容や個別条件に関するご質問は、「個別問合せ」をご利用ください。 | AF7: 1 | AG7: 1 | AH7: 2 | AI7: 0 | AJ7: 0 | AL7: 4 | AM7: 4 | AN7: 0 | AO7: QA231_policy-operations_commute-costs_com-others.md | AP7: 質問 DREAMSの業務一覧に実施済みの「通勤経路申請」のリストが残ったまま消えません。どうすれば消えますか？ 回答 DREAMSの業務一覧のリストは、「社員情報」の作業リストに残っている通勤経路申請を削除すると自動的に消えます。 「社員情報」の作業リストのチェックボックスがグレーアウトされ、ご自身で削除ができない場合には、当方でステータス変更の処理を行いますので、給与アシスト担当サイトのお問い合わせフォームよりご連絡ください。その際、ご自身の氏名と氏名コードをお知らせください。 | AQ7: 0.92797435 | AR7: QA227_policy-operations_commute-costs_com-others.md | AS7: 質問 以下のエラーが表示され、申請できません。どうすればいいですか。 「通勤費に関わる申請が作業リストに保留または承認処理中であるため申請できません」 「申請年月日：202●.●●.●●、株式会社●●で登録した申請が承認待ちのため、新規起票できません。」 回答 DREAMS「社員情報」の「作業リスト」、及び「異動前作業リスト」をご確認いただき、対象のリストが表示されていないか確認（表示されている場合は削除）、 または、DREAMS「進捗管理」の「共通申請」にて「ステータス：承認待ち」で検索いただき、該当リストがないか（該当リストがある場合は取り下げ）確認ください。 ※複数の立場をお持ちの場合は、それぞれの立場でご確認ください。 ※コム出向者については、■1-45もあわせてご確認ください。 | AT7: 0.9236724 | AU7: QA224_policy-operations_commute-costs_com-others.md | AV7: 質問 転居や勤務地変更はありませんが、通勤経路を変更してもいいですか。 回答 不慣れ要素等により、後に認定経路とは異なる経路が最安または最早と判明する場合「一度限り」変更は可能です。 以下の申請時の注意点を参照の上、DREAMSより通勤経路申請を行ってください。 ただし、今後異動や転居等の事由以外での変更は承れなくなるのでご注意をお願いいたします。 【申請時の注意点】 ・「経路変更事由：その他」を設定し、空欄に「一度限りの経路変更」と入力してください。 ・通勤開始日について、定期の場合は、必ず申請月の1日を通勤開始日としてください。 （実績支払やRSの場合を除いて、月途中での変更は承れません。） | AW7: 0.92797435 | AX7: QA180_policy-operations_travel_travel-assignment_office-work_domestic_training_home-travel-expenses_overseas_operational_travel-others.md | AY7: 質問 ドコモグループ外に出向となりました。出向先立場でDREAMSによる赴任旅費申請が出来ません。 回答 異動後の出向先会社での申請手続きとなるため、出向先所属の総括担当等にお問い合わせください。 ※出向先会社によっては、出向元負担の場合もございますので、出向先の総括担当へご確認ください。 | AZ7: 0.9216304 | BT7: 0 | BU7: 0 | BZ7: 0 | CA7: 1 | CB7: 20260519T071352-20260519T182604.csv | CC7: 4 | CD7: user > assistant > tool > assistant | CE7: 1.0.0 | CH7: =IF(OR(CG7="①", CG7="⑤"), "〇", "×") | CI7: =IF(OR(AND($CT7<>"",ISNUMBER(SEARCH($CT7, AP7))),AND($CU7<>"",ISNUMBER(SEARCH($CU7, AP7))),AND($CV7<>"",ISNUMBER(SEARCH($CV7, AP7)))),"〇","-") | CJ7: =IF(OR(AND($CT7<>"",ISNUMBER(SEARCH($CT7, AS7))),AND($CU7<>"",ISNUMBER(SEARCH($CU7, AS7))),AND($CV7<>"",ISNUMBER(SEARCH($CV7, AS7)))),"〇","-") | CK7: =IF(OR(AND($CT7<>"",ISNUMBER(SEARCH($CT7, AV7))),AND($CU7<>"",ISNUMBER(SEARCH($CU7, AV7))),AND($CV7<>"",ISNUMBER(SEARCH($CV7, AV7)))),"〇","-") | CL7: =IF(OR(AND($CT7<>"",ISNUMBER(SEARCH($CT7, AY7))),AND($CU7<>"",ISNUMBER(SEARCH($CU7, AY7))),AND($CV7<>"",ISNUMBER(SEARCH($CV7, AY7)))),"〇","-") | CM7: =IF(OR(AND($CT7<>"",ISNUMBER(SEARCH($CT7, BB7))),AND($CU7<>"",ISNUMBER(SEARCH($CU7, BB7))),AND($CV7<>"",ISNUMBER(SEARCH($CV7, BB7)))),"〇","-") | CN7: =IF(OR(AND($CT7<>"",ISNUMBER(SEARCH($CT7, BE7))),AND($CU7<>"",ISNUMBER(SEARCH($CU7, BE7))),AND($CV7<>"",ISNUMBER(SEARCH($CV7, BE7)))),"〇","-") | CO7: =IF(OR(AND($CT7<>"",ISNUMBER(SEARCH($CT7, BH7))),AND($CU7<>"",ISNUMBER(SEARCH($CU7, BH7))),AND($CV7<>"",ISNUMBER(SEARCH($CV7, BH7)))),"〇","-") | CP7: =IF(OR(AND($CT7<>"",ISNUMBER(SEARCH($CT7, BK7))),AND($CU7<>"",ISNUMBER(SEARCH($CU7, BK7))),AND($CV7<>"",ISNUMBER(SEARCH($CV7, BK7)))),"〇","-") | CQ7: =IF(OR(AND($CT7<>"",ISNUMBER(SEARCH($CT7, BN7))),AND($CU7<>"",ISNUMBER(SEARCH($CU7, BN7))),AND($CV7<>"",ISNUMBER(SEARCH($CV7, BN7)))),"〇","-") | CR7: =IF(OR(AND($CT7<>"",ISNUMBER(SEARCH($CT7, BQ7))),AND($CU7<>"",ISNUMBER(SEARCH($CU7, BQ7))),AND($CV7<>"",ISNUMBER(SEARCH($CV7, BQ7)))),"〇","-") | CW7: =IF(OR(CI7="〇",CJ7="〇",CK7="〇",CL7="〇",CM7="〇",CN7="〇",CO7="〇",CP7="〇",CQ7="〇",CR7="〇"),"〇","") | DE7: =TEXT(U7,"yyyy/mm/dd") | DF7: =VLOOKUP(K7,社員マスタ!C:D,2,0) | DG7: 1779151036941
B8: a:1iSKy7qXCPUl6lHy-2B3xgvRc_tKz1v0JykSQbNaMY5vJSp_4_w19tMqhUwM_oTGTKXV3N-8UzSVsmI-kFbz0LUhY29S-4UuWaWst7uPr3IGvm-BhrKY6KzPsnWAHxMJR-f:9d1db907-bb38-aaeb-0194-7253213ef40d-FB000 | C8: =ROW(A8)-3 | D8: a:1iSKy7qXCPUl6lHy-2B3xgvRc_tKz1v0JykSQbNaMY5vJSp_4_w19tMqhUwM_oTGTKXV3N-8UzSVsmI-kFbz0LUhY29S-4UuWaWst7uPr3IGvm-BhrKY6KzPsnWAHxMJR-f:9d1db907-bb38-aaeb-0194-7253213ef40d | E8: f:9d1db907-bb38-aaeb-0194-7253213ef40d | F8: a:1iSKy7qXCPUl6lHy-2B3xgvRc_tKz1v0JykSQbNaMY5vJSp_4_w19tMqhUwM_oTGTKXV3N-8UzSVsmI-kFbz0LUhY29S-4UuWaWst7uPr3IGvm-BhrKY6KzPsnWAHxMJR | G8: a:1iSKy7qXCPUl6lHy-2B3xgvRc_tKz1v0JykSQbNaMY5vJSp_4_w19tMqhUwM_oTGTKXV3N-8UzSVsmI-kFbz0LUhY29S-4UuWaWst7uPr3IGvm-BhrKY6KzPsnWAHxMJR-S001 | H8: 1 | I8: 4 | J8: 1 | K8: Kazuyo Sorimachi (返町 和代) | L8: DM | N8: リセット | O8: 0 | P8: 1 | Q8: 0 | R8: 0 | S8: 46161.026 | T8: 46161.026 | U8: 46161.401 | V8: 46161.401 | W8: 0 | AB8: 未分類 | AC8: none | AD8: 1 | AF8: 0 | AG8: 0 | AH8: 0 | AI8: 0 | AJ8: 0 | AL8: 0 | AM8: 0 | AN8: 0 | BT8: 0 | BU8: 0 | BZ8: 0 | CA8: 1 | CB8: 20260519T071352-20260519T182604.csv | CC8: 1 | CD8: user | CE8: 1.0.0 | CH8: =IF(OR(CG8="①", CG8="⑤"), "〇", "×") | CI8: =IF(OR(AND($CT8<>"",ISNUMBER(SEARCH($CT8, AP8))),AND($CU8<>"",ISNUMBER(SEARCH($CU8, AP8))),AND($CV8<>"",ISNUMBER(SEARCH($CV8, AP8)))),"〇","-") | CJ8: =IF(OR(AND($CT8<>"",ISNUMBER(SEARCH($CT8, AS8))),AND($CU8<>"",ISNUMBER(SEARCH($CU8, AS8))),AND($CV8<>"",ISNUMBER(SEARCH($CV8, AS8)))),"〇","-") | CK8: =IF(OR(AND($CT8<>"",ISNUMBER(SEARCH($CT8, AV8))),AND($CU8<>"",ISNUMBER(SEARCH($CU8, AV8))),AND($CV8<>"",ISNUMBER(SEARCH($CV8, AV8)))),"〇","-") | CL8: =IF(OR(AND($CT8<>"",ISNUMBER(SEARCH($CT8, AY8))),AND($CU8<>"",ISNUMBER(SEARCH($CU8, AY8))),AND($CV8<>"",ISNUMBER(SEARCH($CV8, AY8)))),"〇","-") | CM8: =IF(OR(AND($CT8<>"",ISNUMBER(SEARCH($CT8, BB8))),AND($CU8<>"",ISNUMBER(SEARCH($CU8, BB8))),AND($CV8<>"",ISNUMBER(SEARCH($CV8, BB8)))),"〇","-") | CN8: =IF(OR(AND($CT8<>"",ISNUMBER(SEARCH($CT8, BE8))),AND($CU8<>"",ISNUMBER(SEARCH($CU8, BE8))),AND($CV8<>"",ISNUMBER(SEARCH($CV8, BE8)))),"〇","-") | CO8: =IF(OR(AND($CT8<>"",ISNUMBER(SEARCH($CT8, BH8))),AND($CU8<>"",ISNUMBER(SEARCH($CU8, BH8))),AND($CV8<>"",ISNUMBER(SEARCH($CV8, BH8)))),"〇","-") | CP8: =IF(OR(AND($CT8<>"",ISNUMBER(SEARCH($CT8, BK8))),AND($CU8<>"",ISNUMBER(SEARCH($CU8, BK8))),AND($CV8<>"",ISNUMBER(SEARCH($CV8, BK8)))),"〇","-") | CQ8: =IF(OR(AND($CT8<>"",ISNUMBER(SEARCH($CT8, BN8))),AND($CU8<>"",ISNUMBER(SEARCH($CU8, BN8))),AND($CV8<>"",ISNUMBER(SEARCH($CV8, BN8)))),"〇","-") | CR8: =IF(OR(AND($CT8<>"",ISNUMBER(SEARCH($CT8, BQ8))),AND($CU8<>"",ISNUMBER(SEARCH($CU8, BQ8))),AND($CV8<>"",ISNUMBER(SEARCH($CV8, BQ8)))),"〇","-") | CW8: =IF(OR(CI8="〇",CJ8="〇",CK8="〇",CL8="〇",CM8="〇",CN8="〇",CO8="〇",CP8="〇",CQ8="〇",CR8="〇"),"〇","") | DE8: =TEXT(U8,"yyyy/mm/dd") | DF8: =VLOOKUP(K8,社員マスタ!C:D,2,0) | DG8: f:9d1db907-bb38-aaeb-0194-7253213ef40d
B9: a:1iSKy7qXCPUl6lHy-2B3xgvRc_tKz1v0JykSQbNaMY5vJSp_4_w19tMqhUwM_oTGTKXV3N-8UzSVsmI-kFbz0LUhY29S-4UuWaWst7uPr3IGvm-BhrKY6KzPsnWAHxMJR-1779151102632-FB000 | C9: =ROW(A9)-3 | D9: a:1iSKy7qXCPUl6lHy-2B3xgvRc_tKz1v0JykSQbNaMY5vJSp_4_w19tMqhUwM_oTGTKXV3N-8UzSVsmI-kFbz0LUhY29S-4UuWaWst7uPr3IGvm-BhrKY6KzPsnWAHxMJR-1779151102632 | E9: 1779151102632 | F9: a:1iSKy7qXCPUl6lHy-2B3xgvRc_tKz1v0JykSQbNaMY5vJSp_4_w19tMqhUwM_oTGTKXV3N-8UzSVsmI-kFbz0LUhY29S-4UuWaWst7uPr3IGvm-BhrKY6KzPsnWAHxMJR | G9: a:1iSKy7qXCPUl6lHy-2B3xgvRc_tKz1v0JykSQbNaMY5vJSp_4_w19tMqhUwM_oTGTKXV3N-8UzSVsmI-kFbz0LUhY29S-4UuWaWst7uPr3IGvm-BhrKY6KzPsnWAHxMJR-S002 | H9: 2 | I9: 1 | J9: 1 | K9: Kazuyo Sorimachi (返町 和代) | L9: DM | M9: 休暇種別のうちの「不稼働」とは何ですか？ どういうときに使うのですか？ 以下の通りDREAMSの休暇種別で選択できます。 | N9: 休暇種別のうちの「不稼働」とは何ですか？ どういうときに使うのですか？ 以下の通りDREAMSの休暇種別で選択できます。 | O9: 1 | P9: 0 | Q9: 0 | R9: 0 | S9: 46161.027 | T9: 46161.027 | U9: 46161.402 | V9: 46161.402 | W9: 5.899 | X9: searchEmployeeRules | Y9: 制度・運用 | AA9: 制度・運用 | AB9: 制度・運用 | AC9: predicted | AD9: 0 | AE9: 「不稼働」とは、業務上の必要により事務の一部または全部が停止され、出勤や勤務ができない場合に使用する休暇種別です。 具体的には、以下のようなケースで「不稼働」が適用されます。 - 業務上の必要に基づき、会社や部署の事務が一時的に停止された場合 - 非常事態の発生などで出勤・勤務が不可能となった場合 このような状況で、所属長が必要と認めた時間や日数について「不稼働」として休暇を取得できます。 ※AIの回答は必ずしも正確ではありません。参照情報も確認いただき、最終判断は所属部署の公式情報をご確認ください。 | AF9: 1 | AG9: 0 | AH9: 3 | AI9: 0 | AJ9: 0 | AL9: 4 | AM9: 4 | AN9: 0 | AO9: 40 特認休暇について_202511.docx | AP9: （注）(1) 休暇を付与する場合であって、特に必要とする場合は、臨時雇を雇用しても差し支えない。 「業務に支障がない場合」には、「業務に支障があるが、臨時雇を雇用すれば業務に支障がなくなる場合」を含む。 ２ 前項による休暇の付与は、次により行うものとする。 (1) 「休暇願」（「人事服務関係の願、届について」（1992年７月１日総第22号）に定める様式）に基づき、組織単位の長（組織単位の長が指定した者（直属上長より上位にある者に限る。）を含む。）が承認する。 (2) １年につき６週間以内であれば、夏季及び冬季の２回付与しても差し支えない。 (3) １学部の受講につき24週間以内であれば、５年以上にわたって付与しても差し支えない。 ３ 第１項に定める休暇は、社員就業規則第37条第２項による休暇とし、有給とする。 ４ 第１項に定める休暇期間中の給与については、基本給、成果手当及び採用調整加算の合算した額の10分の3を減額して得た額並びに子育て・介護手当、単身赴任手当及び住宅補助費の全額を支給するものとする。 この場合、月の初日以外の日において新たにこの休暇を付与した場合又は月の末日以外の日においてこの休暇期間が終了した場合における減額すべき額については、「社員給与規則の解釈運用について」（1992年７月１日総第45号）第11条第１項の算出式に基づき、日割によって計算するものとする。 付 則 １ 本通達は、2023年４月１日から実施する。 ２ 「第５章 大学通信教育のスクーリングに参加する者の服務の取扱について」第４項の休暇期間中の給与において、「社員給与規則」（1992年７月１日社長達第22号）の改正（2023年３月31日）付則第３項ないし第12項の措置額を含めて扱う。 ３ 本通達の実施に伴い、「特認休暇について」（1992年7月1日総第16号）、「ＮＴＴドコモグループ記念日における服務等の取扱いについて」（1992年９月24日総第294号）、「被災者支援活動に従事する社員の服務について」（1995年５月15日総勤第２号）、「骨髄バンクへの登録等を行う社員の服務について」（1993年12月24日総勤第78号）及び「大学通信教育のスクーリングに参加する者の服務の取扱について」（1992年７月１日総第23号）を廃止する。 付 則 | AQ9: 0.92271555 | AR9: 36 社員の勤務時間、休日及び休暇について_202504.docx | AS9: 第３ 特別休暇 １ 休暇の理由及び期間 理 由 期 間 | AT9: 0.92483792 | AU9: 02 臨時雇就業規則_202512.docx | AV9: る。 ２ 前項における出勤率の算定にあたっては、第17条第１項第15号に定める出産のための特別休暇、第20条に定める公傷休暇、第29条に定める育児休職及び第30条に定める介護休職を付与した日は出勤したものとみなす。 ３ 年次休暇を与えた日の賃金は、当該勤務日の所定勤務時間を勤務した場合に支払われる通常の賃金とする。 ４ 年次休暇の時季の指定等の取扱いは次のとおりとする。 （1）年次休暇の時季を指定する場合は事前に行わなければならない。 ただし、指定された時季における年次休暇が事業の正常な運営を妨げる場合は、会社は他の時季に変更することができるものとする。 （2）同条第１項の年次休暇が10日以上発効された臨時雇に対して、発効日から１年以内の年次休暇の取得日数が日又は半日単位で５日に満たない場合は、その不足分について、臨時雇の希望を勘案したうえで会社があらかじめ時季を指定し、日又は半日を単位に取得させることとする。 ５ 年次休暇は、原則として日を単位とするが、１時間を単位とすることもできる。 ただし、１時間を単位とした休暇は、休暇発効日より１年以内において５日を上限とする。 なお、休暇の付与日数が５日に満たない場合、発効された日数を上限とする。 ６ １時間を単位とする場合における取り扱いは、次のとおりとする。 (1) １時間を単位とした休暇は１日の所定勤務時間内において、取得時間帯、取得時間数に制限無く取得できる。 (2) １時間単位の休暇は、１日の所定勤務時間数をもって１日分とする。 特別休暇 第 17 条 臨時雇が次の各号の一に該当する理由により勤務日に勤務しないときは、当該各号に定 めるところにより、その者に特別休暇が与えられる。 | AW9: 0.92271555 | AX9: 12 エキスパート1就業規則_202512.docx | AY9: ２ 本条に規定する特別休暇は濫用してはならない。 | AZ9: 0.92598352 | BT9: 0 | BU9: 0 | BZ9: 0 | CA9: 0 | CB9: 20260519T071352-20260519T182604.csv | CC9: 5 | CD9: user > assistant > assistant > tool > assistant | CE9: 1.0.0 | CH9: =IF(OR(CG9="①", CG9="⑤"), "〇", "×") | CI9: =IF(OR(AND($CT9<>"",ISNUMBER(SEARCH($CT9, AP9))),AND($CU9<>"",ISNUMBER(SEARCH($CU9, AP9))),AND($CV9<>"",ISNUMBER(SEARCH($CV9, AP9)))),"〇","-") | CJ9: =IF(OR(AND($CT9<>"",ISNUMBER(SEARCH($CT9, AS9))),AND($CU9<>"",ISNUMBER(SEARCH($CU9, AS9))),AND($CV9<>"",ISNUMBER(SEARCH($CV9, AS9)))),"〇","-") | CK9: =IF(OR(AND($CT9<>"",ISNUMBER(SEARCH($CT9, AV9))),AND($CU9<>"",ISNUMBER(SEARCH($CU9, AV9))),AND($CV9<>"",ISNUMBER(SEARCH($CV9, AV9)))),"〇","-") | CL9: =IF(OR(AND($CT9<>"",ISNUMBER(SEARCH($CT9, AY9))),AND($CU9<>"",ISNUMBER(SEARCH($CU9, AY9))),AND($CV9<>"",ISNUMBER(SEARCH($CV9, AY9)))),"〇","-") | CM9: =IF(OR(AND($CT9<>"",ISNUMBER(SEARCH($CT9, BB9))),AND($CU9<>"",ISNUMBER(SEARCH($CU9, BB9))),AND($CV9<>"",ISNUMBER(SEARCH($CV9, BB9)))),"〇","-") | CN9: =IF(OR(AND($CT9<>"",ISNUMBER(SEARCH($CT9, BE9))),AND($CU9<>"",ISNUMBER(SEARCH($CU9, BE9))),AND($CV9<>"",ISNUMBER(SEARCH($CV9, BE9)))),"〇","-") | CO9: =IF(OR(AND($CT9<>"",ISNUMBER(SEARCH($CT9, BH9))),AND($CU9<>"",ISNUMBER(SEARCH($CU9, BH9))),AND($CV9<>"",ISNUMBER(SEARCH($CV9, BH9)))),"〇","-") | CP9: =IF(OR(AND($CT9<>"",ISNUMBER(SEARCH($CT9, BK9))),AND($CU9<>"",ISNUMBER(SEARCH($CU9, BK9))),AND($CV9<>"",ISNUMBER(SEARCH($CV9, BK9)))),"〇","-") | CQ9: =IF(OR(AND($CT9<>"",ISNUMBER(SEARCH($CT9, BN9))),AND($CU9<>"",ISNUMBER(SEARCH($CU9, BN9))),AND($CV9<>"",ISNUMBER(SEARCH($CV9, BN9)))),"〇","-") | CR9: =IF(OR(AND($CT9<>"",ISNUMBER(SEARCH($CT9, BQ9))),AND($CU9<>"",ISNUMBER(SEARCH($CU9, BQ9))),AND($CV9<>"",ISNUMBER(SEARCH($CV9, BQ9)))),"〇","-") | CW9: =IF(OR(CI9="〇",CJ9="〇",CK9="〇",CL9="〇",CM9="〇",CN9="〇",CO9="〇",CP9="〇",CQ9="〇",CR9="〇"),"〇","") | DE9: =TEXT(U9,"yyyy/mm/dd") | DF9: =VLOOKUP(K9,社員マスタ!C:D,2,0) | DG9: 1779151102632
B10: a:1iSKy7qXCPUl6lHy-2B3xgvRc_tKz1v0JykSQbNaMY5vJSp_4_w19tMqhUwM_oTGTKXV3N-8UzSVsmI-kFbz0LUhY29S-4UuWaWst7uPr3IGvm-BhrKY6KzPsnWAHxMJR-1779151187894-FB000 | C10: =ROW(A10)-3 | D10: a:1iSKy7qXCPUl6lHy-2B3xgvRc_tKz1v0JykSQbNaMY5vJSp_4_w19tMqhUwM_oTGTKXV3N-8UzSVsmI-kFbz0LUhY29S-4UuWaWst7uPr3IGvm-BhrKY6KzPsnWAHxMJR-1779151187894 | E10: 1779151187894 | F10: a:1iSKy7qXCPUl6lHy-2B3xgvRc_tKz1v0JykSQbNaMY5vJSp_4_w19tMqhUwM_oTGTKXV3N-8UzSVsmI-kFbz0LUhY29S-4UuWaWst7uPr3IGvm-BhrKY6KzPsnWAHxMJR | G10: a:1iSKy7qXCPUl6lHy-2B3xgvRc_tKz1v0JykSQbNaMY5vJSp_4_w19tMqhUwM_oTGTKXV3N-8UzSVsmI-kFbz0LUhY29S-4UuWaWst7uPr3IGvm-BhrKY6KzPsnWAHxMJR-S002 | H10: 2 | I10: 2 | J10: 1 | K10: Kazuyo Sorimachi (返町 和代) | L10: DM | M10: 勤務計画に重ねて（休暇）不稼働 を登録するのはあっていますか？ | N10: 勤務計画に重ねて（休暇）不稼働 を登録するのはあっていますか？ | O10: 1 | P10: 0 | Q10: 0 | R10: 0 | S10: 46161.028 | T10: 46161.028 | U10: 46161.403 | V10: 46161.403 | W10: 2.706 | AB10: 未分類 | AC10: none | AD10: 1 | AE10: はい、勤務計画に重ねて「不稼働」の休暇を登録することは適切です。 「不稼働」は業務の一部または全部が停止される場合に使う休暇種別であり、勤務計画上の勤務予定に対して、その期間に勤務できない状況を反映するために登録します。 したがって、勤務計画に対して「不稼働」を重ねて登録することで、実際の勤務が停止されることを正しく管理できます。 ※AIの回答は必ずしも正確ではありません。参照情報も確認いただき、最終判断は所属部署の公式情報をご確認ください。 | AF10: 1 | AG10: 0 | AH10: 1 | AI10: 0 | AJ10: 0 | AL10: 0 | AM10: 0 | AN10: 0 | BT10: 0 | BU10: 0 | BZ10: 0 | CA10: 0 | CB10: 20260519T071352-20260519T182604.csv | CC10: 2 | CD10: user > assistant | CE10: 1.0.0 | CH10: =IF(OR(CG10="①", CG10="⑤"), "〇", "×") | CI10: =IF(OR(AND($CT10<>"",ISNUMBER(SEARCH($CT10, AP10))),AND($CU10<>"",ISNUMBER(SEARCH($CU10, AP10))),AND($CV10<>"",ISNUMBER(SEARCH($CV10, AP10)))),"〇","-") | CJ10: =IF(OR(AND($CT10<>"",ISNUMBER(SEARCH($CT10, AS10))),AND($CU10<>"",ISNUMBER(SEARCH($CU10, AS10))),AND($CV10<>"",ISNUMBER(SEARCH($CV10, AS10)))),"〇","-") | CK10: =IF(OR(AND($CT10<>"",ISNUMBER(SEARCH($CT10, AV10))),AND($CU10<>"",ISNUMBER(SEARCH($CU10, AV10))),AND($CV10<>"",ISNUMBER(SEARCH($CV10, AV10)))),"〇","-") | CL10: =IF(OR(AND($CT10<>"",ISNUMBER(SEARCH($CT10, AY10))),AND($CU10<>"",ISNUMBER(SEARCH($CU10, AY10))),AND($CV10<>"",ISNUMBER(SEARCH($CV10, AY10)))),"〇","-") | CM10: =IF(OR(AND($CT10<>"",ISNUMBER(SEARCH($CT10, BB10))),AND($CU10<>"",ISNUMBER(SEARCH($CU10, BB10))),AND($CV10<>"",ISNUMBER(SEARCH($CV10, BB10)))),"〇","-") | CN10: =IF(OR(AND($CT10<>"",ISNUMBER(SEARCH($CT10, BE10))),AND($CU10<>"",ISNUMBER(SEARCH($CU10, BE10))),AND($CV10<>"",ISNUMBER(SEARCH($CV10, BE10)))),"〇","-") | CO10: =IF(OR(AND($CT10<>"",ISNUMBER(SEARCH($CT10, BH10))),AND($CU10<>"",ISNUMBER(SEARCH($CU10, BH10))),AND($CV10<>"",ISNUMBER(SEARCH($CV10, BH10)))),"〇","-") | CP10: =IF(OR(AND($CT10<>"",ISNUMBER(SEARCH($CT10, BK10))),AND($CU10<>"",ISNUMBER(SEARCH($CU10, BK10))),AND($CV10<>"",ISNUMBER(SEARCH($CV10, BK10)))),"〇","-") | CQ10: =IF(OR(AND($CT10<>"",ISNUMBER(SEARCH($CT10, BN10))),AND($CU10<>"",ISNUMBER(SEARCH($CU10, BN10))),AND($CV10<>"",ISNUMBER(SEARCH($CV10, BN10)))),"〇","-") | CR10: =IF(OR(AND($CT10<>"",ISNUMBER(SEARCH($CT10, BQ10))),AND($CU10<>"",ISNUMBER(SEARCH($CU10, BQ10))),AND($CV10<>"",ISNUMBER(SEARCH($CV10, BQ10)))),"〇","-") | CW10: =IF(OR(CI10="〇",CJ10="〇",CK10="〇",CL10="〇",CM10="〇",CN10="〇",CO10="〇",CP10="〇",CQ10="〇",CR10="〇"),"〇","") | DE10: =TEXT(U10,"yyyy/mm/dd") | DF10: =VLOOKUP(K10,社員マスタ!C:D,2,0) | DG10: 1779151187894
B11: a:1iSKy7qXCPUl6lHy-2B3xgvRc_tKz1v0JykSQbNaMY5vJSp_4_w19tMqhUwM_oTGTKXV3N-8UzSVsmI-kFbz0LUhY29S-4UuWaWst7uPr3IGvm-BhrKY6KzPsnWAHxMJR-1779151482515-FB000 | C11: =ROW(A11)-3 | D11: a:1iSKy7qXCPUl6lHy-2B3xgvRc_tKz1v0JykSQbNaMY5vJSp_4_w19tMqhUwM_oTGTKXV3N-8UzSVsmI-kFbz0LUhY29S-4UuWaWst7uPr3IGvm-BhrKY6KzPsnWAHxMJR-1779151482515 | E11: 1779151482515 | F11: a:1iSKy7qXCPUl6lHy-2B3xgvRc_tKz1v0JykSQbNaMY5vJSp_4_w19tMqhUwM_oTGTKXV3N-8UzSVsmI-kFbz0LUhY29S-4UuWaWst7uPr3IGvm-BhrKY6KzPsnWAHxMJR | G11: a:1iSKy7qXCPUl6lHy-2B3xgvRc_tKz1v0JykSQbNaMY5vJSp_4_w19tMqhUwM_oTGTKXV3N-8UzSVsmI-kFbz0LUhY29S-4UuWaWst7uPr3IGvm-BhrKY6KzPsnWAHxMJR-S002 | H11: 2 | I11: 3 | J11: 1 | K11: Kazuyo Sorimachi (返町 和代) | L11: DM | M11: 休憩時間について教えてください。 ↓の休憩時間の取り方はあっていますか？ | N11: 休憩時間について教えてください。 ↓の休憩時間の取り方はあっていますか？ | O11: 1 | P11: 0 | Q11: 0 | R11: 0 | S11: 46161.031 | T11: 46161.031 | U11: 46161.406 | V11: 46161.406 | W11: 6.02 | X11: searchEmployeeRules | AB11: 未分類 | AC11: none | AD11: 1 | AE11: 休憩時間の取り方について、以下の内容が基本となります。 - 休憩時間は、少なくとも拘束2時間ごとに15分の割合で与えられます。 - 勤務時間が拘束4時間以下の場合は、休憩が与えられないこともあります。 - 休憩時間は勤務の途中で、継続して取ることも、分割して取ることも可能です。 また、フレックスタイム制の場合は勤務時間に応じて休憩時間が決まります。 - 1日5時間以上7時間未満の勤務：45分 - 1日7時間以上の勤務：60分 ご自身の勤務形態や勤務時間に合わせて、上記のルールに沿って休憩を取ることが正しい取り方です。 ※AIの回答は必ずしも正確ではありません。参照情報も確認いただき、最終判断は所属部署の公式情報をご確認ください。 | AF11: 1 | AG11: 0 | AH11: 2 | AI11: 0 | AJ11: 0 | AL11: 4 | AM11: 4 | AN11: 0 | AO11: 39 勤務時間、休日、休暇、休職及び勤務票等について_202511.docx | AP11: 第３章 深夜勤務に伴う休息時間確保のための配慮措置について 深夜勤務に伴う休息時間確保のための配慮措置については、以下のとおりとする。 １．目的 社員等の健康確保並びに生産性の向上に資する観点から、深夜勤務について原則禁止としているところであるが、真にやむを得ない事由により、深夜勤務を実施した社員等が一定の休息時間を確保できる環境整備に努めることとする。 ２．対象者 管理監督者を含む全雇用区分とする。 ３．午前０時を超える深夜勤務を実施した場合、翌日における勤務時間の弾力的運用 (1) 定型勤務、交替勤務が適用される者 直属上長は、翌日の始終業時刻の変更により、社員等の休息時間を確保できる環境整備に努める。 始業時刻及び終業時刻の変更については、服務種別ごとの始終業時刻設定可能な時間帯において、30分を単位とし社員等の了解を得て実施することができる。 (2) フレックスタイム制が適用される者 直属上長は、翌日の始終業時刻の調整を促すことで、社員等の休息時間を確保できる環境整備に努める。なお、必要に応じてコアタイム解除を行う。 なお、コアタイムを設定しないフレックスタイム制が適用される者については、直属上長は、翌日の始業時刻の調整により、社員等の休息時間を確保できるよう助言指導を行う。 ４．休暇取得の環境整備 午前０時を超える深夜勤務を実施した日の翌日または翌々日について、社員等が年次休暇、ライフプラン休暇の取得を申請する場合は、最大限の配慮を行う。 リフレッシュのためのライフプラン休暇の取得については、休息時間を確保する観点から、午前０時を超える深夜勤務を実施した場合に、原則として深夜勤務明けの日に、日または時間単位のライフプラン休暇の取得を可能とする。 なお、深夜勤務明けの日に勤務した場合は、深夜勤務明けの日の翌日まで取得を可能とする。 第４章 社員の病気休職、刑事休職、解雇、降職及び退職について 社員の病気休職、刑事休職、解雇、降職及び退職については、以下のとおりとする。 第1 休職及び復職 | AQ11: 0.92762333 | AR11: 02 臨時雇就業規則_202512.docx | AS11: ２ 前項の始業及び終業の時刻は、業務の都合又は本人の希望により変更することがある。 休憩時間 第 11 条 休憩時間は、少なくとも拘束２時間について15分の割合で計算した時間を与えられる。 ただし、勤務時間が拘束４時間以下であるときは与えられないことがある。 ２ 休憩時間は勤務の途中において、継続し、又は分割して与えられる。 時間外及び休日の勤務 第 12 条 １日について勤務時間８時間、１週間について勤務時間40時間を超えない限りにおいて第９条及び第14条の規定にかかわらず、１日の所定勤務時間を超えて、又は４週４日以外の休日に勤務を命ぜられることがある。 ２ 次の各号の一に該当する場合においては、前項の規定にかかわらず、時間外又は休日に勤務を命ぜられることがある。 (1) 労働基準法第36条の規定により協定を締結したとき (2) 労働基準法第33条の規定により労働基準監督署に所定の手続きをしたとき ３ 労働基準法第41条第３号の許可を受けた者は、前各項の規定にかかわらず、時間外又は休日に勤務を命ぜられることがある。 第２節 リモートワーク リモートワーク 第 13 条 臨時雇が所属長にリモートワークを申し出たとき、または会社指示により、勤務事業所以外を勤務場所とすることがある。 ２ 会社が貸与する情報通信機器等を除き、リモートワークに関わる費用については、臨時雇が負担する。 第３節 休日及び休暇 休 日 第 14 条 休日は、原則として次のとおりとし、４週４日を下回らないよう個別の雇用契約において定める。 (1) 毎週日曜日及び土曜日 (2) 個別の雇用契約において定めた日 ２ 前項の休日は、業務上やむを得ない理由があるときは、他の日に変更されることがある。 休暇の種類 第 15 条 休暇には、次の種類がある。 （１）有給休暇 ア 年次休暇 イ 特別休暇 ウ 病気休暇 エ 特別連続休暇 （２）無給休暇 ア 看護等休暇 イ 介護のための短期の休暇 （３）その他 ア 公傷休暇 イ 通勤災害休暇 ２ 前項の休暇のほか、社長が必要と認めた場合に休暇が与えられることがある。 年次休暇 | AT11: 0.9280667 | AU11: 健康管理規程.pdf | AV11: ア 日勤服務以外の服務につかせない。ただし、やむを得ぬ理由で夜勤服務につかせる場合は、組織の 長と産業医が協議して決める。 イ 健康状態に応じて、勤務時間中に休養時間を与えるか、又は作業環境、労働負荷を考慮して、勤務 内容の軽減をはかる。 (ｱ) 休養時間中は、原則として事業所内の休憩室等で休養させる。ただし、通勤所要時間、交通機 関等の諸事情を考慮して、勤務の始め又は終りに休養時間を与えることができる。 (ｲ) 休養時間は、１日の所定勤務時間から休養時間を除いた時間が、拘束４時間を下回らない範囲 で与えるものとする。 (ｳ) 勤務内容の軽減をはかる場合には、必要に応じて勤務場所の変更、業務の転換等を行うものと する。 ウ 過激な運動を伴う業務、時間外労働、宿泊出張はさせない。 (3) 要注意（Ｃ）の服務については、次の各項によることとする。 ア 日勤服務以外の服務につかせない。ただし、やむを得ぬ理由で前記の服務以外の服務につかせる場 合は、組織の長と産業医が協議して決める。 イ 時間外労働はさせない。ただし、やむを得ぬ理由で時間外労働をさせる場合は、組織の長と産業医 が協議して決める。この場合においても、１日２時間、１週２回を限度とする。 | AW11: 0.92762333 | AX11: 01 社員就業規則等_202512.docx | AY11: ２ 宿直については、睡眠時間を含み８時間以内の休憩時間が与えられる。 ３ 日直又は宿直の当直時間については、所属長が定めるところによる。 出張、赴任等の場合の勤務時間 第 29 条 社員が出張し、若しくは赴任し、又は所属長のもとを離れて勤務する場合における勤務時間については、特に命ぜられた場合を除くほか、所定の勤務時間を勤務したものとみなす。 第２節 フレックスタイム制 対象者 第 30 条 社員は、第20条から第27条までの規定にかかわらず、次条以下に規定するフレックスタイム制が適用されることがある。 基準労働時間 第 31 条 前条に定める社員は、各清算期間（各月１日から月末まで）において、基準労働時間（週休日を日曜日及び土曜日に設定する社員の当該清算期間における所定労働日の勤務時間（１日７時間30分。ただし、第64条第３項及び第67条第２項に規定する短時間勤務を行う者については、１日４時間、５時間又は６時間のいずれかの時間）を合計して得た時間をいう。）を勤務しなければならない。 コアタイム及びフレキシブルタイム 第 32 条 コアタイム及びフレキシブルタイムは、次のとおりとする。 （１） コアタイム（全員が勤務しなければならない時間帯） ① 標準的なコアタイムは、午前10時から午後３時まで（正午から午後１時までは休憩時間）の４時間とする。 なお、具体的な設定時刻は、労働基準法第32条の３に規定する協定により定める。 ② 第64条第３項及び第67条第２項に規定する短時間勤務を行う者の標準的なコアタイムは、午前10時から午後２時（正午から午後１時までは休憩時間）の３時間とする。なお、具体的な設定時刻は、労働基準法第32条の３に規定する協定により定める。 ③ コアタイムを設定しない場合は、１日の最低勤務時間を３時間とする。 なお、具体的には労働基準法第32条の３に規定する協定により定める。 また、コアタイムを設定しない場合における休憩時間は、次のとおりとし、勤務の途中において適用社員の裁量により設定する。 ア １日５時間以上７時間未満の勤務 45分 イ １日７時間以上の勤務 60分 （２）フレキシブルタイム（社員が自主的に始業・終業時刻を選択できる時間帯） | AZ11: 0.93041365 | BT11: 0 | BU11: 0 | BZ11: 0 | CA11: 0 | CB11: 20260519T071352-20260519T182604.csv | CC11: 4 | CD11: user > assistant > tool > assistant | CE11: 1.0.0 | CH11: =IF(OR(CG11="①", CG11="⑤"), "〇", "×") | CI11: =IF(OR(AND($CT11<>"",ISNUMBER(SEARCH($CT11, AP11))),AND($CU11<>"",ISNUMBER(SEARCH($CU11, AP11))),AND($CV11<>"",ISNUMBER(SEARCH($CV11, AP11)))),"〇","-") | CJ11: =IF(OR(AND($CT11<>"",ISNUMBER(SEARCH($CT11, AS11))),AND($CU11<>"",ISNUMBER(SEARCH($CU11, AS11))),AND($CV11<>"",ISNUMBER(SEARCH($CV11, AS11)))),"〇","-") | CK11: =IF(OR(AND($CT11<>"",ISNUMBER(SEARCH($CT11, AV11))),AND($CU11<>"",ISNUMBER(SEARCH($CU11, AV11))),AND($CV11<>"",ISNUMBER(SEARCH($CV11, AV11)))),"〇","-") | CL11: =IF(OR(AND($CT11<>"",ISNUMBER(SEARCH($CT11, AY11))),AND($CU11<>"",ISNUMBER(SEARCH($CU11, AY11))),AND($CV11<>"",ISNUMBER(SEARCH($CV11, AY11)))),"〇","-") | CM11: =IF(OR(AND($CT11<>"",ISNUMBER(SEARCH($CT11, BB11))),AND($CU11<>"",ISNUMBER(SEARCH($CU11, BB11))),AND($CV11<>"",ISNUMBER(SEARCH($CV11, BB11)))),"〇","-") | CN11: =IF(OR(AND($CT11<>"",ISNUMBER(SEARCH($CT11, BE11))),AND($CU11<>"",ISNUMBER(SEARCH($CU11, BE11))),AND($CV11<>"",ISNUMBER(SEARCH($CV11, BE11)))),"〇","-") | CO11: =IF(OR(AND($CT11<>"",ISNUMBER(SEARCH($CT11, BH11))),AND($CU11<>"",ISNUMBER(SEARCH($CU11, BH11))),AND($CV11<>"",ISNUMBER(SEARCH($CV11, BH11)))),"〇","-") | CP11: =IF(OR(AND($CT11<>"",ISNUMBER(SEARCH($CT11, BK11))),AND($CU11<>"",ISNUMBER(SEARCH($CU11, BK11))),AND($CV11<>"",ISNUMBER(SEARCH($CV11, BK11)))),"〇","-") | CQ11: =IF(OR(AND($CT11<>"",ISNUMBER(SEARCH($CT11, BN11))),AND($CU11<>"",ISNUMBER(SEARCH($CU11, BN11))),AND($CV11<>"",ISNUMBER(SEARCH($CV11, BN11)))),"〇","-") | CR11: =IF(OR(AND($CT11<>"",ISNUMBER(SEARCH($CT11, BQ11))),AND($CU11<>"",ISNUMBER(SEARCH($CU11, BQ11))),AND($CV11<>"",ISNUMBER(SEARCH($CV11, BQ11)))),"〇","-") | CW11: =IF(OR(CI11="〇",CJ11="〇",CK11="〇",CL11="〇",CM11="〇",CN11="〇",CO11="〇",CP11="〇",CQ11="〇",CR11="〇"),"〇","") | DE11: =TEXT(U11,"yyyy/mm/dd") | DF11: =VLOOKUP(K11,社員マスタ!C:D,2,0) | DG11: 1779151482515
B12: a:1iSKy7qXCPUl6lHy-2B3xgvRc_tKz1v0JykSQbNaMY5vJSp_4_w19tMqhUwM_oTGTKXV3N-8UzSVsmI-kFbz0LUhY29S-4UuWaWst7uPr3IGvm-BhrKY6KzPsnWAHxMJR-1779151514894-FB000 | C12: =ROW(A12)-3 | D12: a:1iSKy7qXCPUl6lHy-2B3xgvRc_tKz1v0JykSQbNaMY5vJSp_4_w19tMqhUwM_oTGTKXV3N-8UzSVsmI-kFbz0LUhY29S-4UuWaWst7uPr3IGvm-BhrKY6KzPsnWAHxMJR-1779151514894 | E12: 1779151514894 | F12: a:1iSKy7qXCPUl6lHy-2B3xgvRc_tKz1v0JykSQbNaMY5vJSp_4_w19tMqhUwM_oTGTKXV3N-8UzSVsmI-kFbz0LUhY29S-4UuWaWst7uPr3IGvm-BhrKY6KzPsnWAHxMJR | G12: a:1iSKy7qXCPUl6lHy-2B3xgvRc_tKz1v0JykSQbNaMY5vJSp_4_w19tMqhUwM_oTGTKXV3N-8UzSVsmI-kFbz0LUhY29S-4UuWaWst7uPr3IGvm-BhrKY6KzPsnWAHxMJR-S002 | H12: 2 | I12: 4 | J12: 1 | K12: Kazuyo Sorimachi (返町 和代) | L12: DM | M12: 60分以上の休憩が与えられるケースを教えてください。 | N12: 60分以上の休憩が与えられるケースを教えてください。 | O12: 1 | P12: 0 | Q12: 0 | R12: 0 | S12: 46161.031 | T12: 46161.031 | U12: 46161.406 | V12: 46161.406 | W12: 2.558 | AB12: 未分類 | AC12: none | AD12: 1 | AE12: 検索結果には「60分以上の休憩が与えられるケース」についての具体的な記載はありません。 ただし、一般的なルールとしては、1日の勤務時間が7時間以上の場合に60分の休憩が与えられることが基本です。 60分を超える休憩が与えられるかどうかは、勤務形態や業務の特性、所属長の判断などによる場合がありますので、詳細は勤務先の規定に従うことになります。 ※AIの回答は必ずしも正確ではありません。参照情報も確認いただき、最終判断は所属部署の公式情報をご確認ください。 | AF12: 1 | AG12: 0 | AH12: 1 | AI12: 0 | AJ12: 0 | AL12: 0 | AM12: 0 | AN12: 0 | BT12: 0 | BU12: 0 | BZ12: 0 | CA12: 0 | CB12: 20260519T071352-20260519T182604.csv | CC12: 2 | CD12: user > assistant | CE12: 1.0.0 | CH12: =IF(OR(CG12="①", CG12="⑤"), "〇", "×") | CI12: =IF(OR(AND($CT12<>"",ISNUMBER(SEARCH($CT12, AP12))),AND($CU12<>"",ISNUMBER(SEARCH($CU12, AP12))),AND($CV12<>"",ISNUMBER(SEARCH($CV12, AP12)))),"〇","-") | CJ12: =IF(OR(AND($CT12<>"",ISNUMBER(SEARCH($CT12, AS12))),AND($CU12<>"",ISNUMBER(SEARCH($CU12, AS12))),AND($CV12<>"",ISNUMBER(SEARCH($CV12, AS12)))),"〇","-") | CK12: =IF(OR(AND($CT12<>"",ISNUMBER(SEARCH($CT12, AV12))),AND($CU12<>"",ISNUMBER(SEARCH($CU12, AV12))),AND($CV12<>"",ISNUMBER(SEARCH($CV12, AV12)))),"〇","-") | CL12: =IF(OR(AND($CT12<>"",ISNUMBER(SEARCH($CT12, AY12))),AND($CU12<>"",ISNUMBER(SEARCH($CU12, AY12))),AND($CV12<>"",ISNUMBER(SEARCH($CV12, AY12)))),"〇","-") | CM12: =IF(OR(AND($CT12<>"",ISNUMBER(SEARCH($CT12, BB12))),AND($CU12<>"",ISNUMBER(SEARCH($CU12, BB12))),AND($CV12<>"",ISNUMBER(SEARCH($CV12, BB12)))),"〇","-") | CN12: =IF(OR(AND($CT12<>"",ISNUMBER(SEARCH($CT12, BE12))),AND($CU12<>"",ISNUMBER(SEARCH($CU12, BE12))),AND($CV12<>"",ISNUMBER(SEARCH($CV12, BE12)))),"〇","-") | CO12: =IF(OR(AND($CT12<>"",ISNUMBER(SEARCH($CT12, BH12))),AND($CU12<>"",ISNUMBER(SEARCH($CU12, BH12))),AND($CV12<>"",ISNUMBER(SEARCH($CV12, BH12)))),"〇","-") | CP12: =IF(OR(AND($CT12<>"",ISNUMBER(SEARCH($CT12, BK12))),AND($CU12<>"",ISNUMBER(SEARCH($CU12, BK12))),AND($CV12<>"",ISNUMBER(SEARCH($CV12, BK12)))),"〇","-") | CQ12: =IF(OR(AND($CT12<>"",ISNUMBER(SEARCH($CT12, BN12))),AND($CU12<>"",ISNUMBER(SEARCH($CU12, BN12))),AND($CV12<>"",ISNUMBER(SEARCH($CV12, BN12)))),"〇","-") | CR12: =IF(OR(AND($CT12<>"",ISNUMBER(SEARCH($CT12, BQ12))),AND($CU12<>"",ISNUMBER(SEARCH($CU12, BQ12))),AND($CV12<>"",ISNUMBER(SEARCH($CV12, BQ12)))),"〇","-") | CW12: =IF(OR(CI12="〇",CJ12="〇",CK12="〇",CL12="〇",CM12="〇",CN12="〇",CO12="〇",CP12="〇",CQ12="〇",CR12="〇"),"〇","") | DE12: =TEXT(U12,"yyyy/mm/dd") | DF12: =VLOOKUP(K12,社員マスタ!C:D,2,0) | DG12: 1779151514894
B13: a:1JLO3RMA3dGDJ6trWaPOK9_WG46rAdOWrKm6T_qmj6NMRMZgHtUG8tgujTisHfxPb28jndJqRk-OtgP8ATBjscnD-HNvViO0wGLGYw1bS8Dokd9VThBEKv2raN2Y39SRt-1779158719857-FB000 | C13: =ROW(A13)-3 | D13: a:1JLO3RMA3dGDJ6trWaPOK9_WG46rAdOWrKm6T_qmj6NMRMZgHtUG8tgujTisHfxPb28jndJqRk-OtgP8ATBjscnD-HNvViO0wGLGYw1bS8Dokd9VThBEKv2raN2Y39SRt-1779158719857 | E13: 1779158719857 | F13: a:1JLO3RMA3dGDJ6trWaPOK9_WG46rAdOWrKm6T_qmj6NMRMZgHtUG8tgujTisHfxPb28jndJqRk-OtgP8ATBjscnD-HNvViO0wGLGYw1bS8Dokd9VThBEKv2raN2Y39SRt | G13: a:1JLO3RMA3dGDJ6trWaPOK9_WG46rAdOWrKm6T_qmj6NMRMZgHtUG8tgujTisHfxPb28jndJqRk-OtgP8ATBjscnD-HNvViO0wGLGYw1bS8Dokd9VThBEKv2raN2Y39SRt-S001 | H13: 1 | I13: 1 | J13: 1 | K13: Yuusuke Amano (天野 優介) | L13: DM | M13: タレマネの一次評価と2次評価それぞれみることができる？ | N13: タレマネの一次評価と2次評価それぞれみることができる？ | O13: 1 | P13: 0 | Q13: 0 | R13: 0 | S13: 46161.115 | T13: 46161.115 | U13: 46161.49 | V13: 46161.49 | W13: 5.761 | X13: searchEmployeeRules | Y13: タレマネ > 社員用 | AA13: タレマネ | AB13: タレマネ > 社員用 | AC13: predicted | AD13: 0 | AE13: 検索結果からは、タレマネの一次評価者の情報が古い場合や評価フォームの操作に関する案内が見つかっていますが、「一次評価」と「二次評価」それぞれを閲覧できるかどうかについての具体的な記載はありませんでした。 一次評価者の情報が異なったままの場合や、評価フォームの操作に関しては、下記のURLで詳細が確認できます。 https://www.hdservice1.nttls.co.jp/hc/ja/articles/17842855242519 もし評価の閲覧方法について詳細が必要な場合は、上記URLを参考にしてください。 ※AIの回答は必ずしも正確ではありません。参照情報も確認いただき、最終判断は所属部署の公式情報をご確認ください。 | AF13: 1 | AG13: 0 | AH13: 3 | AI13: 0 | AJ13: 0 | AL13: 4 | AM13: 4 | AN13: 0 | AO13: QA614_system_talemane_talemane-employee.md | AP13: 質問 プロファイル画面から上長設定を行って新上長に変更したが、「一次評価者」が異なったまま(古い情報のまま)となっている場合、どうしたらいいでしょうか。 回答 「一次評価者」が異なったまま(古い情報のまま)となっている場合は以下URLをご確認ください。 https://www.hdservice1.nttls.co.jp/hc/ja/articles/17842855242519 | AQ13: 0.91305703 | AR13: QA609_system_talemane_talemane-employee.md | AS13: 質問 目標設定・評価フォームを「システムステップ」まで進めてしまい動かせなくなった場合、どうしたらいいでしょうか。 回答 目標設定・評価フォームを「システムステップ」まで進めてしまい動かせなくなった場合は以下URLをご確認ください。 https://www.hdservice1.nttls.co.jp/hc/ja/articles/19052461933335 | AT13: 0.90775595 | AU13: QA619_system_talemane_talemane-employee.md | AV13: 質問 目標設定・評価フォームが「ロック」され上長側で記入できない場合、どうしたらいいでしょうか。 回答 目標設定・評価フォームが「ロック」され上長側で記入できない場合は以下URLをご確認ください。 https://www.hdservice1.nttls.co.jp/hc/ja/articles/18295484365591 | AW13: 0.91305703 | AX13: QA604_system_talemane_talemane-employee.md | AY13: 質問 目標設定・評価フォームを既に上長へ送ったのに「署名」を求められる場合、どうしたらいいでしょうか。 回答 目標設定・評価フォームを上長へ送ったのに「署名」を求められる場合は以下URLをご確認ください。 https://www.hdservice1.nttls.co.jp/hc/ja/articles/18241101016983 | AZ13: 0.9051388 | BT13: 0 | BU13: 0 | BZ13: 0 | CA13: 0 | CB13: 20260519T071352-20260519T182604.csv | CC13: 5 | CD13: user > assistant > assistant > tool > assistant | CE13: 1.0.0 | CH13: =IF(OR(CG13="①", CG13="⑤"), "〇", "×") | CI13: =IF(OR(AND($CT13<>"",ISNUMBER(SEARCH($CT13, AP13))),AND($CU13<>"",ISNUMBER(SEARCH($CU13, AP13))),AND($CV13<>"",ISNUMBER(SEARCH($CV13, AP13)))),"〇","-") | CJ13: =IF(OR(AND($CT13<>"",ISNUMBER(SEARCH($CT13, AS13))),AND($CU13<>"",ISNUMBER(SEARCH($CU13, AS13))),AND($CV13<>"",ISNUMBER(SEARCH($CV13, AS13)))),"〇","-") | CK13: =IF(OR(AND($CT13<>"",ISNUMBER(SEARCH($CT13, AV13))),AND($CU13<>"",ISNUMBER(SEARCH($CU13, AV13))),AND($CV13<>"",ISNUMBER(SEARCH($CV13, AV13)))),"〇","-") | CL13: =IF(OR(AND($CT13<>"",ISNUMBER(SEARCH($CT13, AY13))),AND($CU13<>"",ISNUMBER(SEARCH($CU13, AY13))),AND($CV13<>"",ISNUMBER(SEARCH($CV13, AY13)))),"〇","-") | CM13: =IF(OR(AND($CT13<>"",ISNUMBER(SEARCH($CT13, BB13))),AND($CU13<>"",ISNUMBER(SEARCH($CU13, BB13))),AND($CV13<>"",ISNUMBER(SEARCH($CV13, BB13)))),"〇","-") | CN13: =IF(OR(AND($CT13<>"",ISNUMBER(SEARCH($CT13, BE13))),AND($CU13<>"",ISNUMBER(SEARCH($CU13, BE13))),AND($CV13<>"",ISNUMBER(SEARCH($CV13, BE13)))),"〇","-") | CO13: =IF(OR(AND($CT13<>"",ISNUMBER(SEARCH($CT13, BH13))),AND($CU13<>"",ISNUMBER(SEARCH($CU13, BH13))),AND($CV13<>"",ISNUMBER(SEARCH($CV13, BH13)))),"〇","-") | CP13: =IF(OR(AND($CT13<>"",ISNUMBER(SEARCH($CT13, BK13))),AND($CU13<>"",ISNUMBER(SEARCH($CU13, BK13))),AND($CV13<>"",ISNUMBER(SEARCH($CV13, BK13)))),"〇","-") | CQ13: =IF(OR(AND($CT13<>"",ISNUMBER(SEARCH($CT13, BN13))),AND($CU13<>"",ISNUMBER(SEARCH($CU13, BN13))),AND($CV13<>"",ISNUMBER(SEARCH($CV13, BN13)))),"〇","-") | CR13: =IF(OR(AND($CT13<>"",ISNUMBER(SEARCH($CT13, BQ13))),AND($CU13<>"",ISNUMBER(SEARCH($CU13, BQ13))),AND($CV13<>"",ISNUMBER(SEARCH($CV13, BQ13)))),"〇","-") | CW13: =IF(OR(CI13="〇",CJ13="〇",CK13="〇",CL13="〇",CM13="〇",CN13="〇",CO13="〇",CP13="〇",CQ13="〇",CR13="〇"),"〇","") | DE13: =TEXT(U13,"yyyy/mm/dd") | DF13: =VLOOKUP(K13,社員マスタ!C:D,2,0) | DG13: 1779158719857
B14: a:1LUvO3KIgrjNGvMw6gRnBwZOrWZM2ktO1-kHzfdc2V7WGbo6qHI6iWXDVNfEh6DM8-szX0djZvTGtbMN46T9vUbamuuBtU9E9yXNF5dWtyuhP9ieTD5T32rvvBva6dnKz-1779165428360-FB000 | C14: =ROW(A14)-3 | D14: a:1LUvO3KIgrjNGvMw6gRnBwZOrWZM2ktO1-kHzfdc2V7WGbo6qHI6iWXDVNfEh6DM8-szX0djZvTGtbMN46T9vUbamuuBtU9E9yXNF5dWtyuhP9ieTD5T32rvvBva6dnKz-1779165428360 | E14: 1779165428360 | F14: a:1LUvO3KIgrjNGvMw6gRnBwZOrWZM2ktO1-kHzfdc2V7WGbo6qHI6iWXDVNfEh6DM8-szX0djZvTGtbMN46T9vUbamuuBtU9E9yXNF5dWtyuhP9ieTD5T32rvvBva6dnKz | G14: a:1LUvO3KIgrjNGvMw6gRnBwZOrWZM2ktO1-kHzfdc2V7WGbo6qHI6iWXDVNfEh6DM8-szX0djZvTGtbMN46T9vUbamuuBtU9E9yXNF5dWtyuhP9ieTD5T32rvvBva6dnKz-S001 | H14: 1 | I14: 1 | J14: 1 | K14: Mikiko Nakanishi (中西 美木子) | L14: DM | N14: カテゴリ | O14: 0 | P14: 0 | Q14: 0 | R14: 1 | S14: 46161.192 | T14: 46161.192 | U14: 46161.567 | V14: 46161.567 | W14: 0 | AB14: 未分類 | AC14: none | AD14: 1 | AF14: 0 | AG14: 0 | AH14: 0 | AI14: 0 | AJ14: 0 | AL14: 0 | AM14: 0 | AN14: 0 | BT14: 0 | BU14: 0 | BZ14: 0 | CA14: 0 | CB14: 20260519T071352-20260519T182604.csv | CC14: 1 | CD14: user | CE14: 1.0.0 | CF14: no answer found | CH14: =IF(OR(CG14="①", CG14="⑤"), "〇", "×") | CI14: =IF(OR(AND($CT14<>"",ISNUMBER(SEARCH($CT14, AP14))),AND($CU14<>"",ISNUMBER(SEARCH($CU14, AP14))),AND($CV14<>"",ISNUMBER(SEARCH($CV14, AP14)))),"〇","-") | CJ14: =IF(OR(AND($CT14<>"",ISNUMBER(SEARCH($CT14, AS14))),AND($CU14<>"",ISNUMBER(SEARCH($CU14, AS14))),AND($CV14<>"",ISNUMBER(SEARCH($CV14, AS14)))),"〇","-") | CK14: =IF(OR(AND($CT14<>"",ISNUMBER(SEARCH($CT14, AV14))),AND($CU14<>"",ISNUMBER(SEARCH($CU14, AV14))),AND($CV14<>"",ISNUMBER(SEARCH($CV14, AV14)))),"〇","-") | CL14: =IF(OR(AND($CT14<>"",ISNUMBER(SEARCH($CT14, AY14))),AND($CU14<>"",ISNUMBER(SEARCH($CU14, AY14))),AND($CV14<>"",ISNUMBER(SEARCH($CV14, AY14)))),"〇","-") | CM14: =IF(OR(AND($CT14<>"",ISNUMBER(SEARCH($CT14, BB14))),AND($CU14<>"",ISNUMBER(SEARCH($CU14, BB14))),AND($CV14<>"",ISNUMBER(SEARCH($CV14, BB14)))),"〇","-") | CN14: =IF(OR(AND($CT14<>"",ISNUMBER(SEARCH($CT14, BE14))),AND($CU14<>"",ISNUMBER(SEARCH($CU14, BE14))),AND($CV14<>"",ISNUMBER(SEARCH($CV14, BE14)))),"〇","-") | CO14: =IF(OR(AND($CT14<>"",ISNUMBER(SEARCH($CT14, BH14))),AND($CU14<>"",ISNUMBER(SEARCH($CU14, BH14))),AND($CV14<>"",ISNUMBER(SEARCH($CV14, BH14)))),"〇","-") | CP14: =IF(OR(AND($CT14<>"",ISNUMBER(SEARCH($CT14, BK14))),AND($CU14<>"",ISNUMBER(SEARCH($CU14, BK14))),AND($CV14<>"",ISNUMBER(SEARCH($CV14, BK14)))),"〇","-") | CQ14: =IF(OR(AND($CT14<>"",ISNUMBER(SEARCH($CT14, BN14))),AND($CU14<>"",ISNUMBER(SEARCH($CU14, BN14))),AND($CV14<>"",ISNUMBER(SEARCH($CV14, BN14)))),"〇","-") | CR14: =IF(OR(AND($CT14<>"",ISNUMBER(SEARCH($CT14, BQ14))),AND($CU14<>"",ISNUMBER(SEARCH($CU14, BQ14))),AND($CV14<>"",ISNUMBER(SEARCH($CV14, BQ14)))),"〇","-") | CW14: =IF(OR(CI14="〇",CJ14="〇",CK14="〇",CL14="〇",CM14="〇",CN14="〇",CO14="〇",CP14="〇",CQ14="〇",CR14="〇"),"〇","") | DE14: =TEXT(U14,"yyyy/mm/dd") | DF14: =VLOOKUP(K14,社員マスタ!C:D,2,0) | DG14: 1779165428360
B15: a:1LUvO3KIgrjNGvMw6gRnBwZOrWZM2ktO1-kHzfdc2V7WGbo6qHI6iWXDVNfEh6DM8-szX0djZvTGtbMN46T9vUbamuuBtU9E9yXNF5dWtyuhP9ieTD5T32rvvBva6dnKz-f:7c38f845-69e4-4c97-b890-7c24a715e079-FB000 | C15: =ROW(A15)-3 | D15: a:1LUvO3KIgrjNGvMw6gRnBwZOrWZM2ktO1-kHzfdc2V7WGbo6qHI6iWXDVNfEh6DM8-szX0djZvTGtbMN46T9vUbamuuBtU9E9yXNF5dWtyuhP9ieTD5T32rvvBva6dnKz-f:7c38f845-69e4-4c97-b890-7c24a715e079 | E15: f:7c38f845-69e4-4c97-b890-7c24a715e079 | F15: a:1LUvO3KIgrjNGvMw6gRnBwZOrWZM2ktO1-kHzfdc2V7WGbo6qHI6iWXDVNfEh6DM8-szX0djZvTGtbMN46T9vUbamuuBtU9E9yXNF5dWtyuhP9ieTD5T32rvvBva6dnKz | G15: a:1LUvO3KIgrjNGvMw6gRnBwZOrWZM2ktO1-kHzfdc2V7WGbo6qHI6iWXDVNfEh6DM8-szX0djZvTGtbMN46T9vUbamuuBtU9E9yXNF5dWtyuhP9ieTD5T32rvvBva6dnKz-S001 | H15: 1 | I15: 2 | J15: 1 | K15: Mikiko Nakanishi (中西 美木子) | L15: DM | N15: [カテゴリ選択] | O15: 0 | P15: 0 | Q15: 1 | R15: 0 | S15: 46161.193 | T15: 46161.193 | U15: 46161.568 | V15: 46161.568 | W15: 0 | Z15: システム操作 | AB15: システム操作 | AC15: user_selected | AD15: 0 | AF15: 0 | AG15: 0 | AH15: 0 | AI15: 0 | AJ15: 0 | AL15: 0 | AM15: 0 | AN15: 0 | BT15: 0 | BU15: 0 | BZ15: 0 | CA15: 0 | CB15: 20260519T071352-20260519T182604.csv | CC15: 1 | CD15: user | CE15: 1.0.0 | CH15: =IF(OR(CG15="①", CG15="⑤"), "〇", "×") | CI15: =IF(OR(AND($CT15<>"",ISNUMBER(SEARCH($CT15, AP15))),AND($CU15<>"",ISNUMBER(SEARCH($CU15, AP15))),AND($CV15<>"",ISNUMBER(SEARCH($CV15, AP15)))),"〇","-") | CJ15: =IF(OR(AND($CT15<>"",ISNUMBER(SEARCH($CT15, AS15))),AND($CU15<>"",ISNUMBER(SEARCH($CU15, AS15))),AND($CV15<>"",ISNUMBER(SEARCH($CV15, AS15)))),"〇","-") | CK15: =IF(OR(AND($CT15<>"",ISNUMBER(SEARCH($CT15, AV15))),AND($CU15<>"",ISNUMBER(SEARCH($CU15, AV15))),AND($CV15<>"",ISNUMBER(SEARCH($CV15, AV15)))),"〇","-") | CL15: =IF(OR(AND($CT15<>"",ISNUMBER(SEARCH($CT15, AY15))),AND($CU15<>"",ISNUMBER(SEARCH($CU15, AY15))),AND($CV15<>"",ISNUMBER(SEARCH($CV15, AY15)))),"〇","-") | CM15: =IF(OR(AND($CT15<>"",ISNUMBER(SEARCH($CT15, BB15))),AND($CU15<>"",ISNUMBER(SEARCH($CU15, BB15))),AND($CV15<>"",ISNUMBER(SEARCH($CV15, BB15)))),"〇","-") | CN15: =IF(OR(AND($CT15<>"",ISNUMBER(SEARCH($CT15, BE15))),AND($CU15<>"",ISNUMBER(SEARCH($CU15, BE15))),AND($CV15<>"",ISNUMBER(SEARCH($CV15, BE15)))),"〇","-") | CO15: =IF(OR(AND($CT15<>"",ISNUMBER(SEARCH($CT15, BH15))),AND($CU15<>"",ISNUMBER(SEARCH($CU15, BH15))),AND($CV15<>"",ISNUMBER(SEARCH($CV15, BH15)))),"〇","-") | CP15: =IF(OR(AND($CT15<>"",ISNUMBER(SEARCH($CT15, BK15))),AND($CU15<>"",ISNUMBER(SEARCH($CU15, BK15))),AND($CV15<>"",ISNUMBER(SEARCH($CV15, BK15)))),"〇","-") | CQ15: =IF(OR(AND($CT15<>"",ISNUMBER(SEARCH($CT15, BN15))),AND($CU15<>"",ISNUMBER(SEARCH($CU15, BN15))),AND($CV15<>"",ISNUMBER(SEARCH($CV15, BN15)))),"〇","-") | CR15: =IF(OR(AND($CT15<>"",ISNUMBER(SEARCH($CT15, BQ15))),AND($CU15<>"",ISNUMBER(SEARCH($CU15, BQ15))),AND($CV15<>"",ISNUMBER(SEARCH($CV15, BQ15)))),"〇","-") | CW15: =IF(OR(CI15="〇",CJ15="〇",CK15="〇",CL15="〇",CM15="〇",CN15="〇",CO15="〇",CP15="〇",CQ15="〇",CR15="〇"),"〇","") | DE15: =TEXT(U15,"yyyy/mm/dd") | DF15: =VLOOKUP(K15,社員マスタ!C:D,2,0) | DG15: f:7c38f845-69e4-4c97-b890-7c24a715e079
B16: a:1LUvO3KIgrjNGvMw6gRnBwZOrWZM2ktO1-kHzfdc2V7WGbo6qHI6iWXDVNfEh6DM8-szX0djZvTGtbMN46T9vUbamuuBtU9E9yXNF5dWtyuhP9ieTD5T32rvvBva6dnKz-f:e0621053-12fb-5c23-0389-27dd460e7c84-FB000 | C16: =ROW(A16)-3 | D16: a:1LUvO3KIgrjNGvMw6gRnBwZOrWZM2ktO1-kHzfdc2V7WGbo6qHI6iWXDVNfEh6DM8-szX0djZvTGtbMN46T9vUbamuuBtU9E9yXNF5dWtyuhP9ieTD5T32rvvBva6dnKz-f:e0621053-12fb-5c23-0389-27dd460e7c84 | E16: f:e0621053-12fb-5c23-0389-27dd460e7c84 | F16: a:1LUvO3KIgrjNGvMw6gRnBwZOrWZM2ktO1-kHzfdc2V7WGbo6qHI6iWXDVNfEh6DM8-szX0djZvTGtbMN46T9vUbamuuBtU9E9yXNF5dWtyuhP9ieTD5T32rvvBva6dnKz | G16: a:1LUvO3KIgrjNGvMw6gRnBwZOrWZM2ktO1-kHzfdc2V7WGbo6qHI6iWXDVNfEh6DM8-szX0djZvTGtbMN46T9vUbamuuBtU9E9yXNF5dWtyuhP9ieTD5T32rvvBva6dnKz-S001 | H16: 1 | I16: 3 | J16: 1 | K16: Mikiko Nakanishi (中西 美木子) | L16: DM | N16: [カテゴリ選択] | O16: 0 | P16: 0 | Q16: 1 | R16: 0 | S16: 46161.193 | T16: 46161.193 | U16: 46161.568 | V16: 46161.568 | W16: 0 | Z16: システム操作 > タレマネ | AB16: システム操作 > タレマネ | AC16: user_selected | AD16: 0 | AF16: 0 | AG16: 0 | AH16: 0 | AI16: 0 | AJ16: 0 | AL16: 0 | AM16: 0 | AN16: 0 | BT16: 0 | BU16: 0 | BZ16: 0 | CA16: 0 | CB16: 20260519T071352-20260519T182604.csv | CC16: 1 | CD16: user | CE16: 1.0.0 | CH16: =IF(OR(CG16="①", CG16="⑤"), "〇", "×") | CI16: =IF(OR(AND($CT16<>"",ISNUMBER(SEARCH($CT16, AP16))),AND($CU16<>"",ISNUMBER(SEARCH($CU16, AP16))),AND($CV16<>"",ISNUMBER(SEARCH($CV16, AP16)))),"〇","-") | CJ16: =IF(OR(AND($CT16<>"",ISNUMBER(SEARCH($CT16, AS16))),AND($CU16<>"",ISNUMBER(SEARCH($CU16, AS16))),AND($CV16<>"",ISNUMBER(SEARCH($CV16, AS16)))),"〇","-") | CK16: =IF(OR(AND($CT16<>"",ISNUMBER(SEARCH($CT16, AV16))),AND($CU16<>"",ISNUMBER(SEARCH($CU16, AV16))),AND($CV16<>"",ISNUMBER(SEARCH($CV16, AV16)))),"〇","-") | CL16: =IF(OR(AND($CT16<>"",ISNUMBER(SEARCH($CT16, AY16))),AND($CU16<>"",ISNUMBER(SEARCH($CU16, AY16))),AND($CV16<>"",ISNUMBER(SEARCH($CV16, AY16)))),"〇","-") | CM16: =IF(OR(AND($CT16<>"",ISNUMBER(SEARCH($CT16, BB16))),AND($CU16<>"",ISNUMBER(SEARCH($CU16, BB16))),AND($CV16<>"",ISNUMBER(SEARCH($CV16, BB16)))),"〇","-") | CN16: =IF(OR(AND($CT16<>"",ISNUMBER(SEARCH($CT16, BE16))),AND($CU16<>"",ISNUMBER(SEARCH($CU16, BE16))),AND($CV16<>"",ISNUMBER(SEARCH($CV16, BE16)))),"〇","-") | CO16: =IF(OR(AND($CT16<>"",ISNUMBER(SEARCH($CT16, BH16))),AND($CU16<>"",ISNUMBER(SEARCH($CU16, BH16))),AND($CV16<>"",ISNUMBER(SEARCH($CV16, BH16)))),"〇","-") | CP16: =IF(OR(AND($CT16<>"",ISNUMBER(SEARCH($CT16, BK16))),AND($CU16<>"",ISNUMBER(SEARCH($CU16, BK16))),AND($CV16<>"",ISNUMBER(SEARCH($CV16, BK16)))),"〇","-") | CQ16: =IF(OR(AND($CT16<>"",ISNUMBER(SEARCH($CT16, BN16))),AND($CU16<>"",ISNUMBER(SEARCH($CU16, BN16))),AND($CV16<>"",ISNUMBER(SEARCH($CV16, BN16)))),"〇","-") | CR16: =IF(OR(AND($CT16<>"",ISNUMBER(SEARCH($CT16, BQ16))),AND($CU16<>"",ISNUMBER(SEARCH($CU16, BQ16))),AND($CV16<>"",ISNUMBER(SEARCH($CV16, BQ16)))),"〇","-") | CW16: =IF(OR(CI16="〇",CJ16="〇",CK16="〇",CL16="〇",CM16="〇",CN16="〇",CO16="〇",CP16="〇",CQ16="〇",CR16="〇"),"〇","") | DE16: =TEXT(U16,"yyyy/mm/dd") | DF16: =VLOOKUP(K16,社員マスタ!C:D,2,0) | DG16: f:e0621053-12fb-5c23-0389-27dd460e7c84
